Workbook
Name lstCategorias: Parametros!$A$11:$A$16
Name lstUnidades: Parametros!$B$11:$B$14
Name lstCriticidade: Parametros!$C$11:$C$13
Name lstCentros: Parametros!$D$11:$D$15
Name lstTipoMov: Parametros!$E$11:$E$12
Name lstMeses: Parametros!$F$11:$F$13
Name pMargemAtencao: Parametros!$B$5
Name pInicioPeriodo: Parametros!$B$6
Name pFimPeriodo: Parametros!$B$7

Sheet LEIA_ME
A1: Lobo Insights Industrial – V0.1 Foundation (dados + Excel base)
A2: Dados 100% sintéticos utilizados exclusivamente para estudo e portfólio.
A4: Pergunta central | B4: O que aconteceu na operação e o que precisa de atenção? (análise do PRESENTE e do histórico; não há previsão de demanda neste projeto).
A5: Versão / escopo | B5: V0.1 – dados sintéticos, tabelas estruturadas, verificações de qualidade e indicadores básicos. Sem dashboard (V0.2), sem IA, sem Power BI, sem n8n.
A6: Fonte oficial dos números | B6: Os três CSVs da pasta data/. As abas Materiais, Estoque e Consumo são cópias desses CSVs (tbMateriais, tbEstoque, tbConsumo). Nenhum número é digitado à mão nas abas de resultado.
A8: Abas
A9: Materiais | B9: Catálogo fictício (20 materiais, 6 categorias). Tabela tbMateriais.
A10: Estoque | B10: Posição de estoque fictícia (20 itens) + colunas calculadas Status_Estoque e Critico_Em_Risco. Tabela tbEstoque.
A11: Consumo | B11: Movimentações fictícias (180), 3 meses consecutivos + colunas calculadas Custo_Movimentado e Mes. Tabela tbConsumo.
A12: Qualidade | B12: 36 verificações (Q01–Q36) em fórmulas ao vivo: teste, regra, resultado, quantidade de erros e status.
A13: Indicadores | B13: 6 KPIs, resumos por mês, categoria, centro e material, e conferências internas (cada resumo precisa fechar com o KPI).
A14: Parametros | B14: Margem de ATENÇÃO, período de análise e listas de valores válidos (usadas pela validação de dados).
A16: Legenda de cores | B16: Cabeçalho azul-marinho = coluna importada do CSV. Cabeçalho verde = coluna calculada por fórmula. Célula amarela com texto azul = parâmetro editável (aba Parametros).
A17: Status de estoque | B17: REPOR: Estoque_Atual <= Estoque_Minimo. ATENÇÃO: Estoque_Atual > Mínimo e <= Mínimo x (1 + Margem_ATENCAO; padrão 25%, editável na aba Parametros). OK: acima disso. É apenas o estado ATUAL – não é previsão nem cálculo de reposição.
A18: Critico_Em_Risco | B18: Sim quando Criticidade = Alta e Status_Estoque = REPOR.
A19: Custo estimado | B19: Custo_Movimentado = Quantidade x Custo_Unitario (arredondado a 2 casas). Custos e moeda são fictícios.
A20: Funções usadas | B20: SOMASES (SUMIFS), CONT.SES (COUNTIFS), SE (IF), SEERRO (IFERROR), ÍNDICE+CORRESP (INDEX+MATCH, alternativa compatível ao PROCX), SOMARPRODUTO (SUMPRODUCT), tabelas estruturadas, validação de dados e formatação condicional. O arquivo grava os nomes em inglês; o Excel exibe no idioma do seu programa.
A21: Como validar | B21: 1) Aba Qualidade: todos PASS. 2) Aba Indicadores, seção 6: todas as conferências OK. 3) Compare os KPIs com scripts/validar_dados.py e docs/TEST_REPORT.md (cálculo independente em Python a partir dos CSVs).
A22: Não incluído na V0.1 | B22: Tabelas dinâmicas (PivotTables) não foram criadas nesta versão: os resumos usam fórmulas SOMASES/CONT.SES, que são reconciliáveis com os CSVs. Painel/gráficos: V0.2.
A24: SHA-256 dos CSVs de origem
A25: consumo_ficticio.csv | B25: b5b8249731e5fcbce34b4345b4d1e576c568b33de3eba4dfca91f8bd0d94233c
A26: estoque_ficticio.csv | B26: 9f90cd52f208f9f863b2ababf7fed4735bbe893ef137efdc79f7506b3359a8d0
A27: materiais_ficticios.csv | B27: eca98597dc740956b4db95885ec54693def431a56501ea6d055fa54c1654231b
A29: Uso | B29: Somente estudo e portfólio. Nenhum uso operacional real. Veja docs/LIMITATIONS.md.

Sheet Materiais
A1: Material_ID | B1: Material | C1: Categoria | D1: Unidade | E1: Custo_Unitario | F1: Criticidade | G1: Fornecedor
A2: MAT001 | B2: Disco de Desbaste 7 pol | C2: Abrasivos | D2: UN | E2: 9.8 | F2: Média | G2: Fornecedor Beta
A3: MAT002 | B3: Disco Flap 4,5 pol Grão 60 | C3: Abrasivos | D3: UN | E3: 7.4 | F3: Baixa | G3: Fornecedor Beta
A4: MAT003 | B4: Lixa de Ferro Grão 80 | C4: Abrasivos | D4: PCT | E4: 38 | F4: Baixa | G4: Fornecedor Gama
A5: MAT004 | B5: Bico de Contato MIG 1,0 mm | C5: Soldagem | D5: PCT | E5: 45 | F5: Média | G5: Fornecedor Delta
A6: MAT005 | B6: Eletrodo Revestido 2,5 mm | C6: Soldagem | D6: CX | E6: 96 | F6: Alta | G6: Fornecedor Alfa
A7: MAT006 | B7: Arame MIG 1,0 mm Bobina | C7: Soldagem | D7: UN | E7: 210 | F7: Alta | G7: Fornecedor Delta
A8: MAT007 | B8: Disco de Corte 7 pol | C8: Corte | D8: UN | E8: 12.5 | F8: Alta | G8: Fornecedor Alfa
A9: MAT008 | B9: Disco de Corte 4,5 pol | C9: Corte | D9: UN | E9: 5.9 | F9: Média | G9: Fornecedor Alfa
A10: MAT009 | B10: Serra Copo 51 mm | C10: Corte | D10: UN | E10: 46 | F10: Baixa | G10: Fornecedor Sigma
A11: MAT010 | B11: Lâmina de Serra Sabre | C11: Corte | D11: PCT | E11: 62 | F11: Média | G11: Fornecedor Sigma
A12: MAT011 | B12: Cabo Flexível 2,5 mm² Rolo | C12: Elétrica | D12: UN | E12: 285 | F12: Média | G12: Fornecedor Beta
A13: MAT012 | B13: Fita Isolante 19 mm | C13: Elétrica | D13: PCT | E13: 42 | F13: Baixa | G13: Fornecedor Gama
... A21: MAT020 | B21: Broca de Aço Rápido 10 mm | C21: Ferramentas | D21: UN | E21: 21 | F21: Média | G21: Fornecedor Alfa

Sheet Estoque
A1: Material_ID | B1: Material | C1: Categoria | D1: Unidade | E1: Estoque_Atual | F1: Estoque_Minimo | G1: Custo_Unitario | H1: Lead_Time_Dias | I1: Fornecedor | J1: Criticidade | K1: Status_Estoque | L1: Critico_Em_Risco
A2: MAT001 | B2: Disco de Desbaste 7 pol | C2: Abrasivos | D2: UN | E2: 120 | F2: 40 | G2: 9.8 | H2: 7 | I2: Fornecedor Beta | J2: Média | K2: =IF(tbEstoque[[#This Row],[Estoque_Atual]]<=tbEstoque[[#This Row],[Estoque_Minimo]],"REPOR",IF(tbEstoque[[#This Row],[Estoque_Atual]]<=tbEstoque[[#This Row],[Estoque_Minimo]]*(1+pMargemAtencao),"ATENÇÃO","OK")) -> OK | L2: =IF(AND(tbEstoque[[#This Row],[Criticidade]]="Alta",tbEstoque[[#This Row],[Status_Estoque]]="REPOR"),"Sim","Não") -> Não
A3: MAT002 | B3: Disco Flap 4,5 pol Grão 60 | C3: Abrasivos | D3: UN | E3: 30 | F3: 30 | G3: 7.4 | H3: 7 | I3: Fornecedor Beta | J3: Baixa | K3: =IF(tbEstoque[[#This Row],[Estoque_Atual]]<=tbEstoque[[#This Row],[Estoque_Minimo]],"REPOR",IF(tbEstoque[[#This Row],[Estoque_Atual]]<=tbEstoque[[#This Row],[Estoque_Minimo]]*(1+pMargemAtencao),"ATENÇÃO","OK")) -> REPOR | L3: =IF(AND(tbEstoque[[#This Row],[Criticidade]]="Alta",tbEstoque[[#This Row],[Status_Estoque]]="REPOR"),"Sim","Não") -> Não
A4: MAT003 | B4: Lixa de Ferro Grão 80 | C4: Abrasivos | D4: PCT | E4: 34 | F4: 10 | G4: 38 | H4: 10 | I4: Fornecedor Gama | J4: Baixa | K4: =IF(tbEstoque[[#This Row],[Estoque_Atual]]<=tbEstoque[[#This Row],[Estoque_Minimo]],"REPOR",IF(tbEstoque[[#This Row],[Estoque_Atual]]<=tbEstoque[[#This Row],[Estoque_Minimo]]*(1+pMargemAtencao),"ATENÇÃO","OK")) -> OK | L4: =IF(AND(tbEstoque[[#This Row],[Criticidade]]="Alta",tbEstoque[[#This Row],[Status_Estoque]]="REPOR"),"Sim","Não") -> Não
A5: MAT004 | B5: Bico de Contato MIG 1,0 mm | C5: Soldagem | D5: PCT | E5: 9 | F5: 8 | G5: 45 | H5: 14 | I5: Fornecedor Delta | J5: Média | K5: =IF(tbEstoque[[#This Row],[Estoque_Atual]]<=tbEstoque[[#This Row],[Estoque_Minimo]],"REPOR",IF(tbEstoque[[#This Row],[Estoque_Atual]]<=tbEstoque[[#This Row],[Estoque_Minimo]]*(1+pMargemAtencao),"ATENÇÃO","OK")) -> ATENÇÃO | L5: =IF(AND(tbEstoque[[#This Row],[Criticidade]]="Alta",tbEstoque[[#This Row],[Status_Estoque]]="REPOR"),"Sim","Não") -> Não
A6: MAT005 | B6: Eletrodo Revestido 2,5 mm | C6: Soldagem | D6: CX | E6: 7 | F6: 12 | G6: 96 | H6: 12 | I6: Fornecedor Alfa | J6: Alta | K6: =IF(tbEstoque[[#This Row],[Estoque_Atual]]<=tbEstoque[[#This Row],[Estoque_Minimo]],"REPOR",IF(tbEstoque[[#This Row],[Estoque_Atual]]<=tbEstoque[[#This Row],[Estoque_Minimo]]*(1+pMargemAtencao),"ATENÇÃO","OK")) -> REPOR | L6: =IF(AND(tbEstoque[[#This Row],[Criticidade]]="Alta",tbEstoque[[#This Row],[Status_Estoque]]="REPOR"),"Sim","Não") -> Sim
A7: MAT006 | B7: Arame MIG 1,0 mm Bobina | C7: Soldagem | D7: UN | E7: 14 | F7: 6 | G7: 210 | H7: 21 | I7: Fornecedor Delta | J7: Alta | K7: =IF(tbEstoque[[#This Row],[Estoque_Atual]]<=tbEstoque[[#This Row],[Estoque_Minimo]],"REPOR",IF(tbEstoque[[#This Row],[Estoque_Atual]]<=tbEstoque[[#This Row],[Estoque_Minimo]]*(1+pMargemAtencao),"ATENÇÃO","OK")) -> OK | L7: =IF(AND(tbEstoque[[#This Row],[Criticidade]]="Alta",tbEstoque[[#This Row],[Status_Estoque]]="REPOR"),"Sim","Não") -> Não
A8: MAT007 | B8: Disco de Corte 7 pol | C8: Corte | D8: UN | E8: 74 | F8: 60 | G8: 12.5 | H8: 7 | I8: Fornecedor Alfa | J8: Alta | K8: =IF(tbEstoque[[#This Row],[Estoque_Atual]]<=tbEstoque[[#This Row],[Estoque_Minimo]],"REPOR",IF(tbEstoque[[#This Row],[Estoque_Atual]]<=tbEstoque[[#This Row],[Estoque_Minimo]]*(1+pMargemAtencao),"ATENÇÃO","OK")) -> ATENÇÃO | L8: =IF(AND(tbEstoque[[#This Row],[Criticidade]]="Alta",tbEstoque[[#This Row],[Status_Estoque]]="REPOR"),"Sim","Não") -> Não
A9: MAT008 | B9: Disco de Corte 4,5 pol | C9: Corte | D9: UN | E9: 210 | F9: 80 | G9: 5.9 | H9: 7 | I9: Fornecedor Alfa | J9: Média | K9: =IF(tbEstoque[[#This Row],[Estoque_Atual]]<=tbEstoque[[#This Row],[Estoque_Minimo]],"REPOR",IF(tbEstoque[[#This Row],[Estoque_Atual]]<=tbEstoque[[#This Row],[Estoque_Minimo]]*(1+pMargemAtencao),"ATENÇÃO","OK")) -> OK | L9: =IF(AND(tbEstoque[[#This Row],[Criticidade]]="Alta",tbEstoque[[#This Row],[Status_Estoque]]="REPOR"),"Sim","Não") -> Não
A10: MAT009 | B10: Serra Copo 51 mm | C10: Corte | D10: UN | E10: 12 | F10: 4 | G10: 46 | H10: 15 | I10: Fornecedor Sigma | J10: Baixa | K10: =IF(tbEstoque[[#This Row],[Estoque_Atual]]<=tbEstoque[[#This Row],[Estoque_Minimo]],"REPOR",IF(tbEstoque[[#This Row],[Estoque_Atual]]<=tbEstoque[[#This Row],[Estoque_Minimo]]*(1+pMargemAtencao),"ATENÇÃO","OK")) -> OK | L10: =IF(AND(tbEstoque[[#This Row],[Criticidade]]="Alta",tbEstoque[[#This Row],[Status_Estoque]]="REPOR"),"Sim","Não") -> Não
A11: MAT010 | B11: Lâmina de Serra Sabre | C11: Corte | D11: PCT | E11: 5 | F11: 6 | G11: 62 | H11: 18 | I11: Fornecedor Sigma | J11: Média | K11: =IF(tbEstoque[[#This Row],[Estoque_Atual]]<=tbEstoque[[#This Row],[Estoque_Minimo]],"REPOR",IF(tbEstoque[[#This Row],[Estoque_Atual]]<=tbEstoque[[#This Row],[Estoque_Minimo]]*(1+pMargemAtencao),"ATENÇÃO","OK")) -> REPOR | L11: =IF(AND(tbEstoque[[#This Row],[Criticidade]]="Alta",tbEstoque[[#This Row],[Status_Estoque]]="REPOR"),"Sim","Não") -> Não
A12: MAT011 | B12: Cabo Flexível 2,5 mm² Rolo | C12: Elétrica | D12: UN | E12: 8 | F12: 3 | G12: 285 | H12: 20 | I12: Fornecedor Beta | J12: Média | K12: =IF(tbEstoque[[#This Row],[Estoque_Atual]]<=tbEstoque[[#This Row],[Estoque_Minimo]],"REPOR",IF(tbEstoque[[#This Row],[Estoque_Atual]]<=tbEstoque[[#This Row],[Estoque_Minimo]]*(1+pMargemAtencao),"ATENÇÃO","OK")) -> OK | L12: =IF(AND(tbEstoque[[#This Row],[Criticidade]]="Alta",tbEstoque[[#This Row],[Status_Estoque]]="REPOR"),"Sim","Não") -> Não
A13: MAT012 | B13: Fita Isolante 19 mm | C13: Elétrica | D13: PCT | E13: 25 | F13: 10 | G13: 42 | H13: 10 | I13: Fornecedor Gama | J13: Baixa | K13: =IF(tbEstoque[[#This Row],[Estoque_Atual]]<=tbEstoque[[#This Row],[Estoque_Minimo]],"REPOR",IF(tbEstoque[[#This Row],[Estoque_Atual]]<=tbEstoque[[#This Row],[Estoque_Minimo]]*(1+pMargemAtencao),"ATENÇÃO","OK")) -> OK | L13: =IF(AND(tbEstoque[[#This Row],[Criticidade]]="Alta",tbEstoque[[#This Row],[Status_Estoque]]="REPOR"),"Sim","Não") -> Não
... A21: MAT020 | B21: Broca de Aço Rápido 10 mm | C21: Ferramentas | D21: UN | E21: 26 | F21: 10 | G21: 21 | H21: 12 | I21: Fornecedor Alfa | J21: Média | K21: =IF(tbEstoque[[#This Row],[Estoque_Atual]]<=tbEstoque[[#This Row],[Estoque_Minimo]],"REPOR",IF(tbEstoque[[#This Row],[Estoque_Atual]]<=tbEstoque[[#This Row],[Estoque_Minimo]]*(1+pMargemAtencao),"ATENÇÃO","OK")) -> OK | L21: =IF(AND(tbEstoque[[#This Row],[Criticidade]]="Alta",tbEstoque[[#This Row],[Status_Estoque]]="REPOR"),"Sim","Não") -> Não

Sheet Consumo
A1: Movimento_ID | B1: Data | C1: Material_ID | D1: Material | E1: Categoria | F1: Quantidade | G1: Unidade | H1: Custo_Unitario | I1: Centro_Trabalho | J1: Tipo_Movimentacao | K1: Custo_Movimentado | L1: Mes
A2: MOV0001 | B2: 46174 | C2: MAT004 | D2: Bico de Contato MIG 1,0 mm | E2: Soldagem | F2: 2 | G2: PCT | H2: 45 | I2: SOLDAGEM | J2: Consumo | K2: =ROUND(tbConsumo[[#This Row],[Quantidade]]*tbConsumo[[#This Row],[Custo_Unitario]],2) -> 90 | L2: =YEAR(tbConsumo[[#This Row],[Data]])&"-"&TEXT(MONTH(tbConsumo[[#This Row],[Data]]),"00") -> 2026-06
A3: MOV0002 | B3: 46175 | C3: MAT020 | D3: Broca de Aço Rápido 10 mm | E3: Ferramentas | F3: 1 | G3: UN | H3: 21 | I3: ELETRICA | J3: Consumo | K3: =ROUND(tbConsumo[[#This Row],[Quantidade]]*tbConsumo[[#This Row],[Custo_Unitario]],2) -> 21 | L3: =YEAR(tbConsumo[[#This Row],[Data]])&"-"&TEXT(MONTH(tbConsumo[[#This Row],[Data]]),"00") -> 2026-06
A4: MOV0003 | B4: 46176 | C4: MAT018 | D4: Chave Combinada 17 mm | E4: Ferramentas | F4: 2 | G4: UN | H4: 24 | I4: MANUTENCAO | J4: Consumo | K4: =ROUND(tbConsumo[[#This Row],[Quantidade]]*tbConsumo[[#This Row],[Custo_Unitario]],2) -> 48 | L4: =YEAR(tbConsumo[[#This Row],[Data]])&"-"&TEXT(MONTH(tbConsumo[[#This Row],[Data]]),"00") -> 2026-06
A5: MOV0004 | B5: 46176 | C5: MAT018 | D5: Chave Combinada 17 mm | E5: Ferramentas | F5: 1 | G5: UN | H5: 24 | I5: MANUTENCAO | J5: Consumo | K5: =ROUND(tbConsumo[[#This Row],[Quantidade]]*tbConsumo[[#This Row],[Custo_Unitario]],2) -> 24 | L5: =YEAR(tbConsumo[[#This Row],[Data]])&"-"&TEXT(MONTH(tbConsumo[[#This Row],[Data]]),"00") -> 2026-06
A6: MOV0005 | B6: 46176 | C6: MAT001 | D6: Disco de Desbaste 7 pol | E6: Abrasivos | F6: 10 | G6: UN | H6: 9.8 | I6: MANUTENCAO | J6: Consumo | K6: =ROUND(tbConsumo[[#This Row],[Quantidade]]*tbConsumo[[#This Row],[Custo_Unitario]],2) -> 98 | L6: =YEAR(tbConsumo[[#This Row],[Data]])&"-"&TEXT(MONTH(tbConsumo[[#This Row],[Data]]),"00") -> 2026-06
A7: MOV0006 | B7: 46177 | C7: MAT003 | D7: Lixa de Ferro Grão 80 | E7: Abrasivos | F7: 1 | G7: PCT | H7: 38 | I7: SOLDAGEM | J7: Consumo | K7: =ROUND(tbConsumo[[#This Row],[Quantidade]]*tbConsumo[[#This Row],[Custo_Unitario]],2) -> 38 | L7: =YEAR(tbConsumo[[#This Row],[Data]])&"-"&TEXT(MONTH(tbConsumo[[#This Row],[Data]]),"00") -> 2026-06
A8: MOV0007 | B8: 46177 | C8: MAT012 | D8: Fita Isolante 19 mm | E8: Elétrica | F8: 2 | G8: PCT | H8: 42 | I8: ELETRICA | J8: Consumo | K8: =ROUND(tbConsumo[[#This Row],[Quantidade]]*tbConsumo[[#This Row],[Custo_Unitario]],2) -> 84 | L8: =YEAR(tbConsumo[[#This Row],[Data]])&"-"&TEXT(MONTH(tbConsumo[[#This Row],[Data]]),"00") -> 2026-06
A9: MOV0008 | B9: 46177 | C9: MAT001 | D9: Disco de Desbaste 7 pol | E9: Abrasivos | F9: 15 | G9: UN | H9: 9.8 | I9: MANUTENCAO | J9: Consumo | K9: =ROUND(tbConsumo[[#This Row],[Quantidade]]*tbConsumo[[#This Row],[Custo_Unitario]],2) -> 147 | L9: =YEAR(tbConsumo[[#This Row],[Data]])&"-"&TEXT(MONTH(tbConsumo[[#This Row],[Data]]),"00") -> 2026-06
A10: MOV0009 | B10: 46177 | C10: MAT018 | D10: Chave Combinada 17 mm | E10: Ferramentas | F10: 2 | G10: UN | H10: 24 | I10: MANUTENCAO | J10: Consumo | K10: =ROUND(tbConsumo[[#This Row],[Quantidade]]*tbConsumo[[#This Row],[Custo_Unitario]],2) -> 48 | L10: =YEAR(tbConsumo[[#This Row],[Data]])&"-"&TEXT(MONTH(tbConsumo[[#This Row],[Data]]),"00") -> 2026-06
A11: MOV0010 | B11: 46177 | C11: MAT017 | D11: Máscara Respiratória PFF2 | E11: EPI | F11: 3 | G11: CX | H11: 72 | I11: FABRICACAO | J11: Consumo | K11: =ROUND(tbConsumo[[#This Row],[Quantidade]]*tbConsumo[[#This Row],[Custo_Unitario]],2) -> 216 | L11: =YEAR(tbConsumo[[#This Row],[Data]])&"-"&TEXT(MONTH(tbConsumo[[#This Row],[Data]]),"00") -> 2026-06
A12: MOV0011 | B12: 46178 | C12: MAT011 | D12: Cabo Flexível 2,5 mm² Rolo | E12: Elétrica | F12: 1 | G12: UN | H12: 285 | I12: FABRICACAO | J12: Consumo | K12: =ROUND(tbConsumo[[#This Row],[Quantidade]]*tbConsumo[[#This Row],[Custo_Unitario]],2) -> 285 | L12: =YEAR(tbConsumo[[#This Row],[Data]])&"-"&TEXT(MONTH(tbConsumo[[#This Row],[Data]]),"00") -> 2026-06
A13: MOV0012 | B13: 46178 | C13: MAT004 | D13: Bico de Contato MIG 1,0 mm | E13: Soldagem | F13: 2 | G13: PCT | H13: 45 | I13: MECANICA | J13: Consumo | K13: =ROUND(tbConsumo[[#This Row],[Quantidade]]*tbConsumo[[#This Row],[Custo_Unitario]],2) -> 90 | L13: =YEAR(tbConsumo[[#This Row],[Data]])&"-"&TEXT(MONTH(tbConsumo[[#This Row],[Data]]),"00") -> 2026-06
... A181: MOV0180 | B181: 46265 | C181: MAT007 | D181: Disco de Corte 7 pol | E181: Corte | F181: 12 | G181: UN | H181: 12.5 | I181: MECANICA | J181: Consumo | K181: =ROUND(tbConsumo[[#This Row],[Quantidade]]*tbConsumo[[#This Row],[Custo_Unitario]],2) -> 150 | L181: =YEAR(tbConsumo[[#This Row],[Data]])&"-"&TEXT(MONTH(tbConsumo[[#This Row],[Data]]),"00") -> 2026-08

Sheet Qualidade
A1: Qualidade dos dados – verificações ao vivo (fórmulas)
A2: Dados 100% sintéticos utilizados exclusivamente para estudo e portfólio.
A3: Cada linha é uma fórmula sobre tbMateriais, tbEstoque e tbConsumo. Erros = 0 => PASS. O mesmo conjunto (Q01–Q36) é executado de forma independente em Python (scripts/validar_dados.py).
A5: Testes executados | B5: =COUNTA(A10:A45) -> 36
A6: PASS | B6: =COUNTIF(E10:E45,"PASS") -> 36
A7: FAIL | B7: =COUNTIF(E10:E45,"FAIL") -> 0
A9: Teste | B9: Regra | C9: Resultado | D9: Quantidade de erros | E9: Status
A10: Q01 · IDs duplicados – Materiais | B10: Material_ID não se repete (conta linhas envolvidas em duplicidade) | C10: =IF(D10=0,"Nenhum erro encontrado","Erros encontrados") -> Nenhum erro encontrado | D10: =SUMPRODUCT(--(COUNTIF(tbMateriais[Material_ID],tbMateriais[Material_ID])>1)) -> 0 | E10: =IF(D10=0,"PASS","FAIL") -> PASS
A11: Q02 · IDs duplicados – Estoque | B11: Material_ID não se repete na posição de estoque | C11: =IF(D11=0,"Nenhum erro encontrado","Erros encontrados") -> Nenhum erro encontrado | D11: =SUMPRODUCT(--(COUNTIF(tbEstoque[Material_ID],tbEstoque[Material_ID])>1)) -> 0 | E11: =IF(D11=0,"PASS","FAIL") -> PASS
A12: Q03 · IDs duplicados – Consumo | B12: Movimento_ID não se repete | C12: =IF(D12=0,"Nenhum erro encontrado","Erros encontrados") -> Nenhum erro encontrado | D12: =SUMPRODUCT(--(COUNTIF(tbConsumo[Movimento_ID],tbConsumo[Movimento_ID])>1)) -> 0 | E12: =IF(D12=0,"PASS","FAIL") -> PASS
A13: Q04 · Nulos indevidos – Materiais | B13: Nenhuma célula vazia na tabela | C13: =IF(D13=0,"Nenhum erro encontrado","Erros encontrados") -> Nenhum erro encontrado | D13: =COUNTBLANK(tbMateriais) -> 0 | E13: =IF(D13=0,"PASS","FAIL") -> PASS
A14: Q05 · Nulos indevidos – Estoque | B14: Nenhuma célula vazia na tabela | C14: =IF(D14=0,"Nenhum erro encontrado","Erros encontrados") -> Nenhum erro encontrado | D14: =COUNTBLANK(tbEstoque) -> 0 | E14: =IF(D14=0,"PASS","FAIL") -> PASS
A15: Q06 · Nulos indevidos – Consumo | B15: Nenhuma célula vazia na tabela | C15: =IF(D15=0,"Nenhum erro encontrado","Erros encontrados") -> Nenhum erro encontrado | D15: =COUNTBLANK(tbConsumo) -> 0 | E15: =IF(D15=0,"PASS","FAIL") -> PASS
A16: Q07 · Quantidade inválida – Consumo | B16: Quantidade numérica, inteira e > 0 | C16: =IF(D16=0,"Nenhum erro encontrado","Erros encontrados") -> Nenhum erro encontrado | D16: =IF(ROWS(tbConsumo[Quantidade])-COUNT(tbConsumo[Quantidade])>0,ROWS(tbConsumo[Quantidade])-COUNT(tbConsumo[Quantidade]),COUNTIF(tbConsumo[Quantidade],"<=0")+SUMPRODUCT(--(tbConsumo[Quantidade]<>INT(tbConsumo[Quantidade])))) -> 0 | E16: =IF(D16=0,"PASS","FAIL") -> PASS
A17: Q08 · Custo <= 0 – Materiais | B17: Custo_Unitario numérico e > 0 | C17: =IF(D17=0,"Nenhum erro encontrado","Erros encontrados") -> Nenhum erro encontrado | D17: =IF(ROWS(tbMateriais[Custo_Unitario])-COUNT(tbMateriais[Custo_Unitario])>0,ROWS(tbMateriais[Custo_Unitario])-COUNT(tbMateriais[Custo_Unitario]),COUNTIF(tbMateriais[Custo_Unitario],"<=0")) -> 0 | E17: =IF(D17=0,"PASS","FAIL") -> PASS
A18: Q09 · Custo <= 0 – Estoque | B18: Custo_Unitario numérico e > 0 | C18: =IF(D18=0,"Nenhum erro encontrado","Erros encontrados") -> Nenhum erro encontrado | D18: =IF(ROWS(tbEstoque[Custo_Unitario])-COUNT(tbEstoque[Custo_Unitario])>0,ROWS(tbEstoque[Custo_Unitario])-COUNT(tbEstoque[Custo_Unitario]),COUNTIF(tbEstoque[Custo_Unitario],"<=0")) -> 0 | E18: =IF(D18=0,"PASS","FAIL") -> PASS
A19: Q10 · Custo <= 0 – Consumo | B19: Custo_Unitario numérico e > 0 | C19: =IF(D19=0,"Nenhum erro encontrado","Erros encontrados") -> Nenhum erro encontrado | D19: =IF(ROWS(tbConsumo[Custo_Unitario])-COUNT(tbConsumo[Custo_Unitario])>0,ROWS(tbConsumo[Custo_Unitario])-COUNT(tbConsumo[Custo_Unitario]),COUNTIF(tbConsumo[Custo_Unitario],"<=0")) -> 0 | E19: =IF(D19=0,"PASS","FAIL") -> PASS
A20: Q11 · Material inexistente – Estoque | B20: Material_ID do estoque existe no catálogo | C20: =IF(D20=0,"Nenhum erro encontrado","Erros encontrados") -> Nenhum erro encontrado | D20: =SUMPRODUCT(--(COUNTIF(tbMateriais[Material_ID],tbEstoque[Material_ID])=0)) -> 0 | E20: =IF(D20=0,"PASS","FAIL") -> PASS
A21: Q12 · Material inexistente – Consumo | B21: Material_ID do consumo existe no catálogo | C21: =IF(D21=0,"Nenhum erro encontrado","Erros encontrados") -> Nenhum erro encontrado | D21: =SUMPRODUCT(--(COUNTIF(tbMateriais[Material_ID],tbConsumo[Material_ID])=0)) -> 0 | E21: =IF(D21=0,"PASS","FAIL") -> PASS
A22: Q13 · Catálogo sem estoque | B22: Todo material do catálogo tem posição de estoque | C22: =IF(D22=0,"Nenhum erro encontrado","Erros encontrados") -> Nenhum erro encontrado | D22: =SUMPRODUCT(--(COUNTIF(tbEstoque[Material_ID],tbMateriais[Material_ID])=0)) -> 0 | E22: =IF(D22=0,"PASS","FAIL") -> PASS
A23: Q14 · Nome divergente – Estoque | B23: Material do estoque = catálogo | C23: =IF(D23=0,"Nenhum erro encontrado","Erros encontrados") -> Nenhum erro encontrado | D23: =SUMPRODUCT((COUNTIF(tbMateriais[Material_ID],tbEstoque[Material_ID])>0)*(COUNTIFS(tbMateriais[Material_ID],tbEstoque[Material_ID],tbMateriais[Material],tbEstoque[Material])=0)) -> 0 | E23: =IF(D23=0,"PASS","FAIL") -> PASS
A24: Q15 · Nome divergente – Consumo | B24: Material do consumo = catálogo | C24: =IF(D24=0,"Nenhum erro encontrado","Erros encontrados") -> Nenhum erro encontrado | D24: =SUMPRODUCT((COUNTIF(tbMateriais[Material_ID],tbConsumo[Material_ID])>0)*(COUNTIFS(tbMateriais[Material_ID],tbConsumo[Material_ID],tbMateriais[Material],tbConsumo[Material])=0)) -> 0 | E24: =IF(D24=0,"PASS","FAIL") -> PASS
A25: Q16 · Categoria divergente – Estoque | B25: Categoria do estoque = catálogo | C25: =IF(D25=0,"Nenhum erro encontrado","Erros encontrados") -> Nenhum erro encontrado | D25: =SUMPRODUCT((COUNTIF(tbMateriais[Material_ID],tbEstoque[Material_ID])>0)*(COUNTIFS(tbMateriais[Material_ID],tbEstoque[Material_ID],tbMateriais[Categoria],tbEstoque[Categoria])=0)) -> 0 | E25: =IF(D25=0,"PASS","FAIL") -> PASS
A26: Q17 · Categoria divergente – Consumo | B26: Categoria do consumo = catálogo | C26: =IF(D26=0,"Nenhum erro encontrado","Erros encontrados") -> Nenhum erro encontrado | D26: =SUMPRODUCT((COUNTIF(tbMateriais[Material_ID],tbConsumo[Material_ID])>0)*(COUNTIFS(tbMateriais[Material_ID],tbConsumo[Material_ID],tbMateriais[Categoria],tbConsumo[Categoria])=0)) -> 0 | E26: =IF(D26=0,"PASS","FAIL") -> PASS
A27: Q18 · Unidade divergente – Estoque | B27: Unidade do estoque = catálogo | C27: =IF(D27=0,"Nenhum erro encontrado","Erros encontrados") -> Nenhum erro encontrado | D27: =SUMPRODUCT((COUNTIF(tbMateriais[Material_ID],tbEstoque[Material_ID])>0)*(COUNTIFS(tbMateriais[Material_ID],tbEstoque[Material_ID],tbMateriais[Unidade],tbEstoque[Unidade])=0)) -> 0 | E27: =IF(D27=0,"PASS","FAIL") -> PASS
A28: Q19 · Unidade divergente – Consumo | B28: Unidade do consumo = catálogo | C28: =IF(D28=0,"Nenhum erro encontrado","Erros encontrados") -> Nenhum erro encontrado | D28: =SUMPRODUCT((COUNTIF(tbMateriais[Material_ID],tbConsumo[Material_ID])>0)*(COUNTIFS(tbMateriais[Material_ID],tbConsumo[Material_ID],tbMateriais[Unidade],tbConsumo[Unidade])=0)) -> 0 | E28: =IF(D28=0,"PASS","FAIL") -> PASS
A29: Q20 · Custo divergente – Estoque | B29: Custo_Unitario do estoque = catálogo | C29: =IF(D29=0,"Nenhum erro encontrado","Erros encontrados") -> Nenhum erro encontrado | D29: =SUMPRODUCT((COUNTIF(tbMateriais[Material_ID],tbEstoque[Material_ID])>0)*(COUNTIFS(tbMateriais[Material_ID],tbEstoque[Material_ID],tbMateriais[Custo_Unitario],tbEstoque[Custo_Unitario])=0)) -> 0 | E29: =IF(D29=0,"PASS","FAIL") -> PASS
A30: Q21 · Custo divergente – Consumo | B30: Custo_Unitario do consumo = catálogo | C30: =IF(D30=0,"Nenhum erro encontrado","Erros encontrados") -> Nenhum erro encontrado | D30: =SUMPRODUCT((COUNTIF(tbMateriais[Material_ID],tbConsumo[Material_ID])>0)*(COUNTIFS(tbMateriais[Material_ID],tbConsumo[Material_ID],tbMateriais[Custo_Unitario],tbConsumo[Custo_Unitario])=0)) -> 0 | E30: =IF(D30=0,"PASS","FAIL") -> PASS
A31: Q22 · Criticidade divergente – Estoque | B31: Criticidade do estoque = catálogo | C31: =IF(D31=0,"Nenhum erro encontrado","Erros encontrados") -> Nenhum erro encontrado | D31: =SUMPRODUCT((COUNTIF(tbMateriais[Material_ID],tbEstoque[Material_ID])>0)*(COUNTIFS(tbMateriais[Material_ID],tbEstoque[Material_ID],tbMateriais[Criticidade],tbEstoque[Criticidade])=0)) -> 0 | E31: =IF(D31=0,"PASS","FAIL") -> PASS
A32: Q23 · Fornecedor divergente – Estoque | B32: Fornecedor do estoque = catálogo | C32: =IF(D32=0,"Nenhum erro encontrado","Erros encontrados") -> Nenhum erro encontrado | D32: =SUMPRODUCT((COUNTIF(tbMateriais[Material_ID],tbEstoque[Material_ID])>0)*(COUNTIFS(tbMateriais[Material_ID],tbEstoque[Material_ID],tbMateriais[Fornecedor],tbEstoque[Fornecedor])=0)) -> 0 | E32: =IF(D32=0,"PASS","FAIL") -> PASS
A33: Q24 · Datas inválidas – Consumo | B33: Data válida e dentro do período definido na aba Parametros | C33: =IF(D33=0,"Nenhum erro encontrado","Erros encontrados") -> Nenhum erro encontrado | D33: =SUMPRODUCT(--NOT(ISNUMBER(tbConsumo[Data])))+COUNTIF(tbConsumo[Data],"<"&pInicioPeriodo)+COUNTIF(tbConsumo[Data],">"&pFimPeriodo) -> 0 | E33: =IF(D33=0,"PASS","FAIL") -> PASS
A34: Q25 · Cobertura dos 3 meses – Consumo | B34: Cada mês do período tem >= 1 movimentação (conta meses sem registro) | C34: =IF(D34=0,"Nenhum erro encontrado","Erros encontrados") -> Nenhum erro encontrado | D34: =SUMPRODUCT(--(COUNTIF(tbConsumo[Mes],lstMeses)=0)) -> 0 | E34: =IF(D34=0,"PASS","FAIL") -> PASS
A35: Q26 · Estoque negativo | B35: Estoque_Atual numérico e >= 0 | C35: =IF(D35=0,"Nenhum erro encontrado","Erros encontrados") -> Nenhum erro encontrado | D35: =IF(ROWS(tbEstoque[Estoque_Atual])-COUNT(tbEstoque[Estoque_Atual])>0,ROWS(tbEstoque[Estoque_Atual])-COUNT(tbEstoque[Estoque_Atual]),COUNTIF(tbEstoque[Estoque_Atual],"<0")) -> 0 | E35: =IF(D35=0,"PASS","FAIL") -> PASS
A36: Q27 · Estoque mínimo negativo | B36: Estoque_Minimo numérico e >= 0 | C36: =IF(D36=0,"Nenhum erro encontrado","Erros encontrados") -> Nenhum erro encontrado | D36: =IF(ROWS(tbEstoque[Estoque_Minimo])-COUNT(tbEstoque[Estoque_Minimo])>0,ROWS(tbEstoque[Estoque_Minimo])-COUNT(tbEstoque[Estoque_Minimo]),COUNTIF(tbEstoque[Estoque_Minimo],"<0")) -> 0 | E36: =IF(D36=0,"PASS","FAIL") -> PASS
A37: Q28 · Lead time inválido | B37: Lead_Time_Dias numérico, inteiro e > 0 | C37: =IF(D37=0,"Nenhum erro encontrado","Erros encontrados") -> Nenhum erro encontrado | D37: =IF(ROWS(tbEstoque[Lead_Time_Dias])-COUNT(tbEstoque[Lead_Time_Dias])>0,ROWS(tbEstoque[Lead_Time_Dias])-COUNT(tbEstoque[Lead_Time_Dias]),COUNTIF(tbEstoque[Lead_Time_Dias],"<=0")+SUMPRODUCT(--(tbEstoque[Lead_Time_Dias]<>INT(tbEstoque[Lead_Time_Dias])))) -> 0 | E37: =IF(D37=0,"PASS","FAIL") -> PASS
A38: Q29 · Categoria inválida – Materiais | B38: Categoria pertence à lista permitida | C38: =IF(D38=0,"Nenhum erro encontrado","Erros encontrados") -> Nenhum erro encontrado | D38: =SUMPRODUCT(--(COUNTIF(lstCategorias,tbMateriais[Categoria])=0)) -> 0 | E38: =IF(D38=0,"PASS","FAIL") -> PASS
A39: Q30 · Categoria inválida – Estoque | B39: Categoria pertence à lista permitida | C39: =IF(D39=0,"Nenhum erro encontrado","Erros encontrados") -> Nenhum erro encontrado | D39: =SUMPRODUCT(--(COUNTIF(lstCategorias,tbEstoque[Categoria])=0)) -> 0 | E39: =IF(D39=0,"PASS","FAIL") -> PASS
A40: Q31 · Categoria inválida – Consumo | B40: Categoria pertence à lista permitida | C40: =IF(D40=0,"Nenhum erro encontrado","Erros encontrados") -> Nenhum erro encontrado | D40: =SUMPRODUCT(--(COUNTIF(lstCategorias,tbConsumo[Categoria])=0)) -> 0 | E40: =IF(D40=0,"PASS","FAIL") -> PASS
A41: Q32 · Unidade inválida – Materiais | B41: Unidade em UN, CX, PCT ou PAR | C41: =IF(D41=0,"Nenhum erro encontrado","Erros encontrados") -> Nenhum erro encontrado | D41: =SUMPRODUCT(--(COUNTIF(lstUnidades,tbMateriais[Unidade])=0)) -> 0 | E41: =IF(D41=0,"PASS","FAIL") -> PASS
A42: Q33 · Criticidade inválida – Materiais | B42: Criticidade em Baixa, Média ou Alta | C42: =IF(D42=0,"Nenhum erro encontrado","Erros encontrados") -> Nenhum erro encontrado | D42: =SUMPRODUCT(--(COUNTIF(lstCriticidade,tbMateriais[Criticidade])=0)) -> 0 | E42: =IF(D42=0,"PASS","FAIL") -> PASS
...

Sheet Indicadores
A1: Indicadores V0.1 – Lobo Insights Industrial
A2: Dados 100% sintéticos utilizados exclusivamente para estudo e portfólio.
A3: Valores monetários em unidade fictícia. Todos os números são fórmulas sobre tbConsumo, tbEstoque e tbMateriais (nada digitado). Este NÃO é o painel final (V0.2).
A4: 1. KPIs principais
A5: KPI | B5: Valor | C5: Como é calculado | G5: Origem
A6: Unidades consumidas | B6: =SUMIFS(tbConsumo[Quantidade],tbConsumo[Tipo_Movimentacao],"Consumo") -> 1647 | C6: Soma de Quantidade das movimentações do tipo Consumo (SOMASES). | G6: tbConsumo[Quantidade]
A7: Custo estimado consumido | B7: =SUMIFS(tbConsumo[Custo_Movimentado],tbConsumo[Tipo_Movimentacao],"Consumo") -> 24606.2 | C7: Soma de Custo_Movimentado (Quantidade x Custo_Unitario) das movimentações de Consumo (SOMASES). Valor fictício. | G7: tbConsumo[Custo_Movimentado]
A8: Movimentações | B8: =COUNTIFS(tbConsumo[Tipo_Movimentacao],"Consumo") -> 180 | C8: Quantidade de registros (linhas) do tipo Consumo (CONT.SES). Não é quantidade de unidades. | G8: tbConsumo[Movimento_ID]
A9: Materiais distintos movimentados | B9: =COUNTIF(B47:B66,">0") -> 20 | C9: Materiais do catálogo com pelo menos 1 movimentação de Consumo (contagem sobre o resumo por material, seção 5). | G9: Seção 5 desta aba
A10: Itens abaixo ou iguais ao mínimo | B10: =COUNTIF(tbEstoque[Status_Estoque],"REPOR") -> 5 | C10: Itens com Status_Estoque = REPOR (Estoque_Atual <= Estoque_Minimo). | G10: tbEstoque[Status_Estoque]
A11: Itens críticos abaixo ou iguais ao mínimo | B11: =COUNTIF(tbEstoque[Critico_Em_Risco],"Sim") -> 2 | C11: Itens com Criticidade = Alta e Estoque_Atual <= Estoque_Minimo (Critico_Em_Risco = Sim). | G11: tbEstoque[Critico_Em_Risco]
A13: Informativo: itens em ATENÇÃO | B13: =COUNTIF(tbEstoque[Status_Estoque],"ATENÇÃO") -> 4 | C13: Atual > Mínimo e Atual <= Mínimo x (1 + margem). Não faz parte dos 6 KPIs.
A14: Informativo: itens de criticidade Alta em ATENÇÃO | B14: =COUNTIFS(tbEstoque[Criticidade],"Alta",tbEstoque[Status_Estoque],"ATENÇÃO") -> 2 | C14: Complementa o KPI 6, que considera apenas REPOR. Não faz parte dos 6 KPIs.
A16: Conferências internas OK | B16: =COUNTIF(E72:E83,"OK")&" de "&ROWS(E72:E83) -> 12 de 12
A19: 2. Resumo por mês
A20: Mês (aaaa-mm) | B20: Movimentações | C20: Unidades consumidas | D20: Custo estimado | E20: % do custo
A21: =Parametros!$F$11 -> 2026-06 | B21: =COUNTIFS(tbConsumo[Mes],$A21,tbConsumo[Tipo_Movimentacao],"Consumo") -> 65 | C21: =SUMIFS(tbConsumo[Quantidade],tbConsumo[Mes],$A21,tbConsumo[Tipo_Movimentacao],"Consumo") -> 608 | D21: =SUMIFS(tbConsumo[Custo_Movimentado],tbConsumo[Mes],$A21,tbConsumo[Tipo_Movimentacao],"Consumo") -> 8456.1 | E21: =IF(D$24=0,0,D21/D$24) -> 0.34365729
A22: =Parametros!$F$12 -> 2026-07 | B22: =COUNTIFS(tbConsumo[Mes],$A22,tbConsumo[Tipo_Movimentacao],"Consumo") -> 75 | C22: =SUMIFS(tbConsumo[Quantidade],tbConsumo[Mes],$A22,tbConsumo[Tipo_Movimentacao],"Consumo") -> 691 | D22: =SUMIFS(tbConsumo[Custo_Movimentado],tbConsumo[Mes],$A22,tbConsumo[Tipo_Movimentacao],"Consumo") -> 10933 | E22: =IF(D$24=0,0,D22/D$24) -> 0.44431891
A23: =Parametros!$F$13 -> 2026-08 | B23: =COUNTIFS(tbConsumo[Mes],$A23,tbConsumo[Tipo_Movimentacao],"Consumo") -> 40 | C23: =SUMIFS(tbConsumo[Quantidade],tbConsumo[Mes],$A23,tbConsumo[Tipo_Movimentacao],"Consumo") -> 348 | D23: =SUMIFS(tbConsumo[Custo_Movimentado],tbConsumo[Mes],$A23,tbConsumo[Tipo_Movimentacao],"Consumo") -> 5217.1 | E23: =IF(D$24=0,0,D23/D$24) -> 0.2120238
A24: Total | B24: =SUM(B21:B23) -> 180 | C24: =SUM(C21:C23) -> 1647 | D24: =SUM(D21:D23) -> 24606.2 | E24: =SUM(E21:E23) -> 1
A26: 3. Resumo por categoria
A27: Categoria | B27: Movimentações | C27: Unidades consumidas | D27: Custo estimado | E27: % do custo
A28: =Parametros!$A$11 -> Abrasivos | B28: =COUNTIFS(tbConsumo[Categoria],$A28,tbConsumo[Tipo_Movimentacao],"Consumo") -> 38 | C28: =SUMIFS(tbConsumo[Quantidade],tbConsumo[Categoria],$A28,tbConsumo[Tipo_Movimentacao],"Consumo") -> 419 | D28: =SUMIFS(tbConsumo[Custo_Movimentado],tbConsumo[Categoria],$A28,tbConsumo[Tipo_Movimentacao],"Consumo") -> 4179.4 | E28: =IF(D$34=0,0,D28/D$34) -> 0.1698515
A29: =Parametros!$A$12 -> Soldagem | B29: =COUNTIFS(tbConsumo[Categoria],$A29,tbConsumo[Tipo_Movimentacao],"Consumo") -> 28 | C29: =SUMIFS(tbConsumo[Quantidade],tbConsumo[Categoria],$A29,tbConsumo[Tipo_Movimentacao],"Consumo") -> 57 | D29: =SUMIFS(tbConsumo[Custo_Movimentado],tbConsumo[Categoria],$A29,tbConsumo[Tipo_Movimentacao],"Consumo") -> 4869 | E29: =IF(D$34=0,0,D29/D$34) -> 0.19787696
A30: =Parametros!$A$13 -> Corte | B30: =COUNTIFS(tbConsumo[Categoria],$A30,tbConsumo[Tipo_Movimentacao],"Consumo") -> 43 | C30: =SUMIFS(tbConsumo[Quantidade],tbConsumo[Categoria],$A30,tbConsumo[Tipo_Movimentacao],"Consumo") -> 940 | D30: =SUMIFS(tbConsumo[Custo_Movimentado],tbConsumo[Categoria],$A30,tbConsumo[Tipo_Movimentacao],"Consumo") -> 7565.3 | E30: =IF(D$34=0,0,D30/D$34) -> 0.30745503
A31: =Parametros!$A$14 -> Elétrica | B31: =COUNTIFS(tbConsumo[Categoria],$A31,tbConsumo[Tipo_Movimentacao],"Consumo") -> 28 | C31: =SUMIFS(tbConsumo[Quantidade],tbConsumo[Categoria],$A31,tbConsumo[Tipo_Movimentacao],"Consumo") -> 45 | D31: =SUMIFS(tbConsumo[Custo_Movimentado],tbConsumo[Categoria],$A31,tbConsumo[Tipo_Movimentacao],"Consumo") -> 4871 | E31: =IF(D$34=0,0,D31/D$34) -> 0.19795824
A32: =Parametros!$A$15 -> EPI | B32: =COUNTIFS(tbConsumo[Categoria],$A32,tbConsumo[Tipo_Movimentacao],"Consumo") -> 34 | C32: =SUMIFS(tbConsumo[Quantidade],tbConsumo[Categoria],$A32,tbConsumo[Tipo_Movimentacao],"Consumo") -> 169 | D32: =SUMIFS(tbConsumo[Custo_Movimentado],tbConsumo[Categoria],$A32,tbConsumo[Tipo_Movimentacao],"Consumo") -> 2751.5 | E32: =IF(D$34=0,0,D32/D$34) -> 0.11182141
A33: =Parametros!$A$16 -> Ferramentas | B33: =COUNTIFS(tbConsumo[Categoria],$A33,tbConsumo[Tipo_Movimentacao],"Consumo") -> 9 | C33: =SUMIFS(tbConsumo[Quantidade],tbConsumo[Categoria],$A33,tbConsumo[Tipo_Movimentacao],"Consumo") -> 17 | D33: =SUMIFS(tbConsumo[Custo_Movimentado],tbConsumo[Categoria],$A33,tbConsumo[Tipo_Movimentacao],"Consumo") -> 370 | E33: =IF(D$34=0,0,D33/D$34) -> 0.015036861
A34: Total | B34: =SUM(B28:B33) -> 180 | C34: =SUM(C28:C33) -> 1647 | D34: =SUM(D28:D33) -> 24606.2 | E34: =SUM(E28:E33) -> 1
A36: 4. Resumo por centro de trabalho
A37: Centro_Trabalho | B37: Movimentações | C37: Unidades consumidas | D37: Custo estimado | E37: % do custo
A38: =Parametros!$D$11 -> MANUTENCAO | B38: =COUNTIFS(tbConsumo[Centro_Trabalho],$A38,tbConsumo[Tipo_Movimentacao],"Consumo") -> 54 | C38: =SUMIFS(tbConsumo[Quantidade],tbConsumo[Centro_Trabalho],$A38,tbConsumo[Tipo_Movimentacao],"Consumo") -> 413 | D38: =SUMIFS(tbConsumo[Custo_Movimentado],tbConsumo[Centro_Trabalho],$A38,tbConsumo[Tipo_Movimentacao],"Consumo") -> 6402.2 | E38: =IF(D$43=0,0,D38/D$43) -> 0.26018646
A39: =Parametros!$D$12 -> SOLDAGEM | B39: =COUNTIFS(tbConsumo[Centro_Trabalho],$A39,tbConsumo[Tipo_Movimentacao],"Consumo") -> 42 | C39: =SUMIFS(tbConsumo[Quantidade],tbConsumo[Centro_Trabalho],$A39,tbConsumo[Tipo_Movimentacao],"Consumo") -> 388 | D39: =SUMIFS(tbConsumo[Custo_Movimentado],tbConsumo[Centro_Trabalho],$A39,tbConsumo[Tipo_Movimentacao],"Consumo") -> 5739.8 | E39: =IF(D$43=0,0,D39/D$43) -> 0.23326641
A40: =Parametros!$D$13 -> FABRICACAO | B40: =COUNTIFS(tbConsumo[Centro_Trabalho],$A40,tbConsumo[Tipo_Movimentacao],"Consumo") -> 32 | C40: =SUMIFS(tbConsumo[Quantidade],tbConsumo[Centro_Trabalho],$A40,tbConsumo[Tipo_Movimentacao],"Consumo") -> 384 | D40: =SUMIFS(tbConsumo[Custo_Movimentado],tbConsumo[Centro_Trabalho],$A40,tbConsumo[Tipo_Movimentacao],"Consumo") -> 4806.5 | E40: =IF(D$43=0,0,D40/D$43) -> 0.19533695
A41: =Parametros!$D$14 -> MECANICA | B41: =COUNTIFS(tbConsumo[Centro_Trabalho],$A41,tbConsumo[Tipo_Movimentacao],"Consumo") -> 30 | C41: =SUMIFS(tbConsumo[Quantidade],tbConsumo[Centro_Trabalho],$A41,tbConsumo[Tipo_Movimentacao],"Consumo") -> 423 | D41: =SUMIFS(tbConsumo[Custo_Movimentado],tbConsumo[Centro_Trabalho],$A41,tbConsumo[Tipo_Movimentacao],"Consumo") -> 3909.7 | E41: =IF(D$43=0,0,D41/D$43) -> 0.15889085
A42: =Parametros!$D$15 -> ELETRICA | B42: =COUNTIFS(tbConsumo[Centro_Trabalho],$A42,tbConsumo[Tipo_Movimentacao],"Consumo") -> 22 | C42: =SUMIFS(tbConsumo[Quantidade],tbConsumo[Centro_Trabalho],$A42,tbConsumo[Tipo_Movimentacao],"Consumo") -> 39 | D42: =SUMIFS(tbConsumo[Custo_Movimentado],tbConsumo[Centro_Trabalho],$A42,tbConsumo[Tipo_Movimentacao],"Consumo") -> 3748 | E42: =IF(D$43=0,0,D42/D$43) -> 0.15231933
A43: Total | B43: =SUM(B38:B42) -> 180 | C43: =SUM(C38:C42) -> 1647 | D43: =SUM(D38:D42) -> 24606.2 | E43: =SUM(E38:E42) -> 1
A45: 5. Resumo por material
A46: Material_ID | B46: Movimentações | C46: Unidades consumidas | D46: Custo estimado | E46: % do custo | F46: Material | G46: Categoria | H46: Criticidade | I46: Estoque_Atual | J46: Status_Estoque
A47: =Materiais!$A$2 -> MAT001 | B47: =COUNTIFS(tbConsumo[Material_ID],$A47,tbConsumo[Tipo_Movimentacao],"Consumo") -> 13 | C47: =SUMIFS(tbConsumo[Quantidade],tbConsumo[Material_ID],$A47,tbConsumo[Tipo_Movimentacao],"Consumo") -> 169 | D47: =SUMIFS(tbConsumo[Custo_Movimentado],tbConsumo[Material_ID],$A47,tbConsumo[Tipo_Movimentacao],"Consumo") -> 1656.2 | E47: =IF(D$67=0,0,D47/D$67) -> 0.067308239 | F47: =IFERROR(INDEX(tbMateriais[Material],MATCH($A47,tbMateriais[Material_ID],0)),"Não encontrado") -> Disco de Desbaste 7 pol | G47: =IFERROR(INDEX(tbMateriais[Categoria],MATCH($A47,tbMateriais[Material_ID],0)),"Não encontrado") -> Abrasivos | H47: =IFERROR(INDEX(tbMateriais[Criticidade],MATCH($A47,tbMateriais[Material_ID],0)),"Não encontrado") -> Média | I47: =IFERROR(INDEX(tbEstoque[Estoque_Atual],MATCH($A47,tbEstoque[Material_ID],0)),"Sem estoque") -> 120 | J47: =IFERROR(INDEX(tbEstoque[Status_Estoque],MATCH($A47,tbEstoque[Material_ID],0)),"Sem estoque") -> OK
...

Sheet Parametros
A1: Parâmetros e listas de valores válidos
A2: Dados 100% sintéticos utilizados exclusivamente para estudo e portfólio.
A4: Parâmetro | B4: Valor | C4: Descrição
A5: Margem_ATENCAO | B5: 0.25 | C5: ATENÇÃO quando Estoque_Atual > Mínimo e <= Mínimo x (1 + margem). Nome definido: pMargemAtencao. Valor de estudo (entrada do autor).
A6: Inicio_Periodo | B6: 46174 | C6: Primeiro dia do período de consumo (3 meses consecutivos, conforme o PDF). Nome: pInicioPeriodo.
A7: Fim_Periodo | B7: 46265 | C7: Último dia do período. Nome: pFimPeriodo.
A10: Categorias | B10: Unidades | C10: Criticidade | D10: Centros de trabalho | E10: Tipos de movimentação | F10: Meses do período (fórmula)
A11: Abrasivos | B11: UN | C11: Baixa | D11: MANUTENCAO | E11: Consumo | F11: =YEAR(EDATE(pInicioPeriodo,0))&"-"&TEXT(MONTH(EDATE(pInicioPeriodo,0)),"00") -> 2026-06
A12: Soldagem | B12: CX | C12: Média | D12: SOLDAGEM | E12: Ajuste | F12: =YEAR(EDATE(pInicioPeriodo,1))&"-"&TEXT(MONTH(EDATE(pInicioPeriodo,1)),"00") -> 2026-07
A13: Corte | B13: PCT | C13: Alta | D13: FABRICACAO | F13: =YEAR(EDATE(pInicioPeriodo,2))&"-"&TEXT(MONTH(EDATE(pInicioPeriodo,2)),"00") -> 2026-08
A14: Elétrica | B14: PAR | D14: MECANICA
A15: EPI | D15: ELETRICA
A16: Ferramentas
A18: Os valores acima são as listas oficiais usadas pela validação de dados e pelas verificações da aba Qualidade. Alterar uma lista muda o que é considerado válido.
