Workbook
Name lstCategorias: Parametros!$A$11:$A$16
Name lstUnidades: Parametros!$B$11:$B$14
Name lstCriticidade: Parametros!$C$11:$C$13
Name lstCentros: Parametros!$D$11:$D$15
Name lstTipoMov: Parametros!$E$11:$E$12
Name lstMeses: Parametros!$F$11:$F$13
Name pMargemAtencao: Parametros!$B$5
Name pInicioPeriodo: Parametros!$B$6
Name pFimPeriodo: Parametros!$B$7
Name pLimitePareto: Parametros!$B$22
Name pTopA: Parametros!$B$23
Name pTopB: Parametros!$B$24

Sheet DASHBOARD
B2: LOBO INSIGHTS INDUSTRIAL | J2: ="Período: "&Analises!B8&" a "&Analises!B10 -> Período: Jun/2026 a Ago/2026
B3: Visão Executiva | Consumo, Custos e Estoque | J3: Dados 100% sintéticos · sem previsão · não é recomendação operacional
B4: Indicadores (KPIs) | D4: Analises (cálculos) | F4: Estoque (dados) | H4: Qualidade dos dados | J4: Parametros | L4: LEIA_ME
B6: Unidades consumidas | D6: Custo estimado consumido | F6: Movimentações | H6: Materiais distintos movimentados | J6: Itens abaixo ou iguais ao mínimo | L6: Itens críticos abaixo ou iguais ao mínimo
B7: =Indicadores!$B$6 -> 1647 | D7: =Indicadores!$B$7 -> 24606.2 | F7: =Indicadores!$B$8 -> 180 | H7: =Indicadores!$B$9 -> 20 | J7: =Indicadores!$B$10 -> 5 | L7: =Indicadores!$B$11 -> 2
B8: ="Média de "&ROUND(Indicadores!$B$6/Indicadores!$B$8,1)&" unidades por movimentação" -> Média de 9.2 unidades por movimentação | D8: ="Média de "&FIXED(Indicadores!$B$7/Indicadores!$B$8,2)&" por movimentação · valor fictício" -> Média de 136.70 por movimentação · valor fictício | F8: ="Registros de consumo em "&ROWS(lstMeses)&" meses ("&Analises!B8&" a "&Analises!B10&")" -> Registros de consumo em 3 meses (Jun/2026 a Ago/2026) | H8: ="de "&ROWS(tbMateriais[Material_ID])&" materiais do catálogo ("&ROUND(Indicadores!$B$9/ROWS(tbMateriais[Material_ID])*100,0)&"%)" -> de 20 materiais do catálogo (100%) | J8: ="de "&ROWS(tbEstoque[Material_ID])&" itens · mais "&COUNTIF(tbEstoque[Status_Estoque],"ATENÇÃO")&" em ATENÇÃO" -> de 20 itens · mais 4 em ATENÇÃO | L8: ="de "&COUNTIF(tbEstoque[Criticidade],"Alta")&" itens de criticidade Alta" -> de 5 itens de criticidade Alta
B10: 1 · Evolução mensal | I10: Variações entre meses vêm dos dados sintéticos; não indicam tendência.
B11: Consumo mensal · unidades | H11: Custo estimado mensal · valor fictício
B21: ="Maior "&"consumo"&": "&INDEX(Analises!$B$8:$B$10,MATCH(MAX(Analises!$D$8:$D$10),Analises!$D$8:$D$10,0))&" ("&FIXED(MAX(Analises!$D$8:$D$10),0)&" un."&")"&CHAR(10)&Analises!B9&" vs "&Analises!B8&": "&IF(ISNUMBER(Analises!F9),IF(Analises!F9>=0,"+","")&ROUND(Analises!F9*100,1)&"%","n/d")&" · "&Analises!B10&" vs "&Analises!B9&": "&IF(ISNUMBER(Analises!F10),IF(Analises!F10>=0,"+","")&ROUND(Analises!F10*100,1)&"%","n/d") -> Maior consumo: Jul/2026 (691 un.) Jul/2026 vs Jun/2026: +13.7% · Ago/2026 vs Jul/2026: -49.6% | H21: ="Maior "&"custo"&": "&INDEX(Analises!$B$8:$B$10,MATCH(MAX(Analises!$E$8:$E$10),Analises!$E$8:$E$10,0))&" ("&FIXED(MAX(Analises!$E$8:$E$10),2)&")"&CHAR(10)&Analises!B9&" vs "&Analises!B8&": "&IF(ISNUMBER(Analises!G9),IF(Analises!G9>=0,"+","")&ROUND(Analises!G9*100,1)&"%","n/d")&" · "&Analises!B10&" vs "&Analises!B9&": "&IF(ISNUMBER(Analises!G10),IF(Analises!G10>=0,"+","")&ROUND(Analises!G10*100,1)&"%","n/d") -> Maior custo: Jul/2026 (10,933.00) Jul/2026 vs Jun/2026: +29.3% · Ago/2026 vs Jul/2026: -52.3%
B23: 2 · Categorias | I23: Ordenado do maior para o menor; % sobre o total do período.
B24: Categorias por consumo · unidades | H24: Categorias por custo · valor fictício
B34: ="Maior consumo: "&Analises!B26&" - "&FIXED(Analises!C26,0)&" un. ("&ROUND(Analises!D26*100,1)&"% do total)"&CHAR(10)&"Menor: "&Analises!B31&" - "&FIXED(Analises!C31,0)&" un. ("&ROUND(Analises!D31*100,1)&"%)" -> Maior consumo: Corte - 940 un. (57.1% do total) Menor: Ferramentas - 17 un. (1%) | H34: ="Maior custo: "&Analises!G26&" - "&FIXED(Analises!H26,2)&" ("&ROUND(Analises!I26*100,1)&"% do total)"&CHAR(10)&"Menor: "&Analises!G31&" - "&FIXED(Analises!H31,2)&" ("&ROUND(Analises!I31*100,1)&"%)" -> Maior custo: Corte - 7,565.30 (30.7% do total) Menor: Ferramentas - 370.00 (1.5%)
B36: 3 · Centros de trabalho | I36: Ordenado do maior para o menor; % sobre o total do período.
B37: Centros de trabalho por consumo · unidades | H37: Centros de trabalho por custo · valor fictício
B46: ="Maior consumo: "&Analises!B45&" - "&FIXED(Analises!C45,0)&" un. ("&ROUND(Analises!D45*100,1)&"% do total)"&CHAR(10)&"Menor: "&Analises!B49&" - "&FIXED(Analises!C49,0)&" un. ("&ROUND(Analises!D49*100,1)&"%)" -> Maior consumo: MECANICA - 423 un. (25.7% do total) Menor: ELETRICA - 39 un. (2.4%) | H46: ="Maior custo: "&Analises!G45&" - "&FIXED(Analises!H45,2)&" ("&ROUND(Analises!I45*100,1)&"% do total)"&CHAR(10)&"Menor: "&Analises!G49&" - "&FIXED(Analises!H49,2)&" ("&ROUND(Analises!I49*100,1)&"%)" -> Maior custo: MANUTENCAO - 6,402.20 (26% do total) Menor: ELETRICA - 3,748.00 (15.2%)
B48: 4 · Materiais · Pareto | I48: Colunas = valor do material; linha = % acumulado; tracejado = limite (aba Parametros).
B49: Pareto de custo por material · valor fictício | H49: Pareto de consumo por material · unidades
B70: =Analises!A129 -> Materiais que somam 80% do custo | D70: ="Custo · "&pTopA&" maiores materiais" -> Custo · 3 maiores materiais | F70: ="Custo · "&pTopB&" maiores materiais" -> Custo · 5 maiores materiais | H70: =Analises!A133 -> Materiais que somam 80% das unidades | J70: ="Consumo · "&pTopA&" maiores materiais" -> Consumo · 3 maiores materiais | L70: ="Consumo · "&pTopB&" maiores materiais" -> Consumo · 5 maiores materiais
B71: =Analises!B129&" de "&Indicadores!$B$9 -> 9 de 20 | D71: =Analises!B131 -> 0.41608619 | F71: =Analises!B132 -> 0.59779649 | H71: =Analises!B133&" de "&Indicadores!$B$9 -> 4 de 20 | J71: =Analises!B135 -> 0.7037037 | L71: =Analises!B136 -> 0.86824529
B72: =ROUND(Analises!B130*100,0)&"% dos materiais movimentados" -> 45% dos materiais movimentados | D72: =Analises!C131&" é o maior em custo" -> Disco de Corte 4,5 pol é o maior em custo | F72: ="do custo estimado total de "&FIXED(Indicadores!$B$7,2) -> do custo estimado total de 24,606.20 | H72: =ROUND(Analises!B134*100,0)&"% dos materiais movimentados" -> 20% dos materiais movimentados | J72: =Analises!C135&" é o maior em unidades" -> Disco de Corte 4,5 pol é o maior em unidades | L72: ="das "&FIXED(Indicadores!$B$6,0)&" unidades consumidas" -> das 1,647 unidades consumidas
B74: 5 · Estoque e criticidade · o que precisa de atenção | I74: Regra do estado atual (não é previsão); parâmetros na aba Parametros.
B75: Fila de atenção · itens em REPOR e ATENÇÃO | H75: Estoque atual × mínimo · itens da fila
B76: Material | D76: Criticidade | E76: Atual | F76: Mínimo | G76: Status
B77: =Analises!B201 -> Eletrodo Revestido 2,5 mm | D77: =Analises!C201 -> Alta | E77: =Analises!D201 -> 7 | F77: =Analises!E201 -> 12 | G77: =Analises!F201 -> REPOR
B78: =Analises!B202 -> Disjuntor Tripolar 32 A | D78: =Analises!C202 -> Alta | E78: =Analises!D202 -> 3 | F78: =Analises!E202 -> 4 | G78: =Analises!F202 -> REPOR
B79: =Analises!B203 -> Luva de Raspa | D79: =Analises!C203 -> Média | E79: =Analises!D203 -> 22 | F79: =Analises!E203 -> 30 | G79: =Analises!F203 -> REPOR
B80: =Analises!B204 -> Lâmina de Serra Sabre | D80: =Analises!C204 -> Média | E80: =Analises!D204 -> 5 | F80: =Analises!E204 -> 6 | G80: =Analises!F204 -> REPOR
B81: =Analises!B205 -> Disco Flap 4,5 pol Grão 60 | D81: =Analises!C205 -> Baixa | E81: =Analises!D205 -> 30 | F81: =Analises!E205 -> 30 | G81: =Analises!F205 -> REPOR
B82: =Analises!B206 -> Máscara Respiratória PFF2 | D82: =Analises!C206 -> Alta | E82: =Analises!D206 -> 11 | F82: =Analises!E206 -> 10 | G82: =Analises!F206 -> ATENÇÃO
B83: =Analises!B207 -> Disco de Corte 7 pol | D83: =Analises!C207 -> Alta | E83: =Analises!D207 -> 74 | F83: =Analises!E207 -> 60 | G83: =Analises!F207 -> ATENÇÃO
B84: =Analises!B208 -> Bico de Contato MIG 1,0 mm | D84: =Analises!C208 -> Média | E84: =Analises!D208 -> 9 | F84: =Analises!E208 -> 8 | G84: =Analises!F208 -> ATENÇÃO
B85: =Analises!B209 -> Terminal de Compressão 6 mm² | D85: =Analises!C209 -> Média | E85: =Analises!D209 -> 14 | F85: =Analises!E209 -> 12 | G85: =Analises!F209 -> ATENÇÃO
B86: =Analises!B210 | D86: =Analises!C210 | E86: =Analises!D210 | F86: =Analises!E210 | G86: =Analises!F210
B88: Criticidade × status | D88: =Analises!B192 -> REPOR | E88: =Analises!C192 -> ATENÇÃO | F88: =Analises!D192 -> OK | G88: =Analises!E192 -> Total
B89: =Analises!A193 -> Alta | D89: =Analises!B193 -> 2 | E89: =Analises!C193 -> 2 | F89: =Analises!D193 -> 1 | G89: =Analises!E193 -> 5
B90: =Analises!A194 -> Média | D90: =Analises!B194 -> 2 | E90: =Analises!C194 -> 2 | F90: =Analises!D194 -> 5 | G90: =Analises!E194 -> 9
B91: =Analises!A195 -> Baixa | D91: =Analises!B195 -> 1 | E91: =Analises!C195 -> 0 | F91: =Analises!D195 -> 5 | G91: =Analises!E195 -> 6
B92: Total | D92: =Analises!B196 -> 5 | E92: =Analises!C196 -> 4 | F92: =Analises!D196 -> 11 | G92: =Analises!E196 -> 20
B93: =COUNTIF(tbEstoque[Status_Estoque],"REPOR")&" em REPOR ("&Indicadores!$B$11&" de criticidade Alta) · "&COUNTIF(tbEstoque[Status_Estoque],"ATENÇÃO")&" em ATENÇÃO ("&COUNTIFS(tbEstoque[Criticidade],"Alta",tbEstoque[Status_Estoque],"ATENÇÃO")&" de criticidade Alta)"&IF(Analises!B212>0,CHAR(10)&"+"&Analises!B212&" item(ns) fora do painel: ver aba Analises, seção 7b","") -> 5 em REPOR (2 de criticidade Alta) · 4 em ATENÇÃO (2 de criticidade Alta) | H93: ="REPOR: atual <= mínimo · ATENÇÃO: até "&ROUND(pMargemAtencao*100,0)&"% acima do mínimo · Crítico em risco: criticidade Alta em REPOR (texto vermelho na fila)" -> REPOR: atual <= mínimo · ATENÇÃO: até 25% acima do mínimo · Crítico em risco: criticidade Alta em REPOR (texto vermelho na fila)
B95: Rastreabilidade: cada número deste painel é fórmula. DASHBOARD ← Analises ← Indicadores ← tbConsumo / tbEstoque / tbMateriais (CSVs em data/).
...

Sheet LEIA_ME
A1: Lobo Insights Industrial – V0.2 Analytics & Dashboard
A2: Dados 100% sintéticos utilizados exclusivamente para estudo e portfólio.
A4: Pergunta central | B4: O que aconteceu na operação e o que precisa de atenção? Análise do PRESENTE e do histórico; este projeto NÃO faz previsão.
A5: Versão / escopo | B5: V0.2 – camada analítica e DASHBOARD sobre a base V0.1.1 (dados, regras, 6 KPIs e fórmulas da V0.1.1 preservados). Sem IA, sem Power BI, sem n8n, sem previsão.
A6: Fonte oficial dos números | B6: Os três CSVs da pasta data/. Materiais, Estoque e Consumo são cópias deles (tbMateriais, tbEstoque, tbConsumo). Nenhum número é digitado nas abas de resultado.
A8: Camadas (do dado à imagem)
A9: Dados | B9: Materiais, Estoque, Consumo (tabelas estruturadas).
A10: Parâmetros | B10: Parametros: margem de ATENÇÃO, período, listas de valores válidos e (V0.2) limite do Pareto e nº de maiores materiais somados.
A11: Validações | B11: Qualidade: 36 verificações ao vivo (Q01–Q36). Indicadores, seção 6, e Analises, seção 8: conferências de fechamento.
A12: Indicadores | B12: Os 6 KPIs oficiais e resumos por mês, categoria, centro e material (V0.1.1, sem alteração de fórmulas).
A13: Cálculos | B13: Analises: evolução mensal, rankings por categoria/centro/material, Pareto de custo e de consumo, concentração, fila de prioridade de estoque, matriz criticidade × status e conferências.
A14: Visualizações | B14: DASHBOARD: 6 cartões de KPI, 9 gráficos (mensal, categoria e centro em unidades e custo; 2 Paretos; estoque atual × mínimo), 6 cartões de concentração, fila de atenção de estoque e leituras geradas por fórmula.
A16: Como ler o DASHBOARD | B16: De cima para baixo: KPIs → evolução mensal → categorias → centros → Pareto de materiais → estoque e criticidade. Os links da faixa superior levam às abas de apoio. Nenhum número é digitado: passe o cursor/selecione a célula para ver a fórmula.
A17: Filtros / segmentações | B17: Não há filtros no DASHBOARD (decisão técnica registrada em docs/V0_2_NOTES.md): segmentações nativas exigem tabelas dinâmicas e não puderam ser verificadas neste ambiente; listas suspensas por fórmula fariam os painéis divergirem dos 6 KPIs oficiais. As tabelas de dados têm filtro de coluna.
A18: Legenda de cores | B18: Cabeçalho azul-marinho = importado do CSV (ou cabeçalho de bloco). Cabeçalho verde = coluna calculada da V0.1.1. Célula amarela com texto azul = parâmetro editável (Parametros). Estoque: vermelho = REPOR, âmbar = ATENÇÃO, verde = OK.
A19: Status de estoque | B19: REPOR: Estoque_Atual <= Estoque_Minimo. ATENÇÃO: Atual > Mínimo e <= Mínimo x (1 + Margem_ATENCAO; padrão 25%). OK: acima disso. É o estado ATUAL – não é previsão nem cálculo de reposição.
A20: Critico_Em_Risco | B20: Sim quando Criticidade = Alta e Status_Estoque = REPOR.
A21: Pareto | B21: Materiais ordenados do maior para o menor valor; % acumulado sobre o total oficial (KPI). 'Núcleo' = materiais necessários para atingir o limite (Parametros, padrão 80%). É descrição do período observado, não regra de gestão.
... A24: Limitações | B24: Dados sintéticos; 3 meses; sem previsão; não testado no Microsoft Excel real (docs/LIMITATIONS.md). Diferenças entre meses vêm do sorteio dos dados, não de fenômeno operacional.
A26: SHA-256 dos CSVs de origem
A27: consumo_ficticio.csv | B27: b5b8249731e5fcbce34b4345b4d1e576c568b33de3eba4dfca91f8bd0d94233c
A28: estoque_ficticio.csv | B28: 9f90cd52f208f9f863b2ababf7fed4735bbe893ef137efdc79f7506b3359a8d0
A29: materiais_ficticios.csv | B29: eca98597dc740956b4db95885ec54693def431a56501ea6d055fa54c1654231b
A31: Uso | B31: Somente estudo e portfólio. Nenhum uso operacional real. Veja docs/LIMITATIONS.md.

Sheet Indicadores
A1: Indicadores – 6 KPIs oficiais e resumos (camada de indicadores; alimenta a aba Analises e o DASHBOARD)
A2: Dados 100% sintéticos utilizados exclusivamente para estudo e portfólio.
A3: Valores monetários em unidade fictícia. Todos os números são fórmulas sobre tbConsumo, tbEstoque e tbMateriais (nada digitado). Conteúdo idêntico ao da V0.1.1; a apresentação executiva está na aba DASHBOARD.
A4: 1. KPIs principais
A5: KPI | B5: Valor | C5: Como é calculado | G5: Origem
A6: Unidades consumidas | B6: =SUMIFS(tbConsumo[Quantidade],tbConsumo[Tipo_Movimentacao],"Consumo") -> 1647 | C6: Soma de Quantidade das movimentações do tipo Consumo (SOMASES). | G6: tbConsumo[Quantidade]
A7: Custo estimado consumido | B7: =SUMIFS(tbConsumo[Custo_Movimentado],tbConsumo[Tipo_Movimentacao],"Consumo") -> 24606.2 | C7: Soma de Custo_Movimentado (Quantidade x Custo_Unitario) das movimentações de Consumo (SOMASES). Valor fictício. | G7: tbConsumo[Custo_Movimentado]
A8: Movimentações | B8: =COUNTIFS(tbConsumo[Tipo_Movimentacao],"Consumo") -> 180 | C8: Quantidade de registros (linhas) do tipo Consumo (CONT.SES). Não é quantidade de unidades. | G8: tbConsumo[Movimento_ID]
A9: Materiais distintos movimentados | B9: =COUNTIF(B47:B66,">0") -> 20 | C9: Materiais do catálogo com pelo menos 1 movimentação de Consumo (contagem sobre o resumo por material, seção 5). | G9: Seção 5 desta aba
A10: Itens abaixo ou iguais ao mínimo | B10: =COUNTIF(tbEstoque[Status_Estoque],"REPOR") -> 5 | C10: Itens com Status_Estoque = REPOR (Estoque_Atual <= Estoque_Minimo). | G10: tbEstoque[Status_Estoque]
A11: Itens críticos abaixo ou iguais ao mínimo | B11: =COUNTIF(tbEstoque[Critico_Em_Risco],"Sim") -> 2 | C11: Itens com Criticidade = Alta e Estoque_Atual <= Estoque_Minimo (Critico_Em_Risco = Sim). | G11: tbEstoque[Critico_Em_Risco]
A13: Informativo: itens em ATENÇÃO | B13: =COUNTIF(tbEstoque[Status_Estoque],"ATENÇÃO") -> 4 | C13: Atual > Mínimo e Atual <= Mínimo x (1 + margem). Não faz parte dos 6 KPIs.
A14: Informativo: itens de criticidade Alta em ATENÇÃO | B14: =COUNTIFS(tbEstoque[Criticidade],"Alta",tbEstoque[Status_Estoque],"ATENÇÃO") -> 2 | C14: Complementa o KPI 6, que considera apenas REPOR. Não faz parte dos 6 KPIs.
A16: Conferências internas OK | B16: =COUNTIF(E72:E83,"OK")&" de "&ROWS(E72:E83) -> 12 de 12
A19: 2. Resumo por mês
A20: Mês (aaaa-mm) | B20: Movimentações | C20: Unidades consumidas | D20: Custo estimado | E20: % do custo
A21: =Parametros!$F$11 -> 2026-06 | B21: =COUNTIFS(tbConsumo[Mes],$A21,tbConsumo[Tipo_Movimentacao],"Consumo") -> 65 | C21: =SUMIFS(tbConsumo[Quantidade],tbConsumo[Mes],$A21,tbConsumo[Tipo_Movimentacao],"Consumo") -> 608 | D21: =SUMIFS(tbConsumo[Custo_Movimentado],tbConsumo[Mes],$A21,tbConsumo[Tipo_Movimentacao],"Consumo") -> 8456.1 | E21: =IF(D$24=0,0,D21/D$24) -> 0.34365729
A22: =Parametros!$F$12 -> 2026-07 | B22: =COUNTIFS(tbConsumo[Mes],$A22,tbConsumo[Tipo_Movimentacao],"Consumo") -> 75 | C22: =SUMIFS(tbConsumo[Quantidade],tbConsumo[Mes],$A22,tbConsumo[Tipo_Movimentacao],"Consumo") -> 691 | D22: =SUMIFS(tbConsumo[Custo_Movimentado],tbConsumo[Mes],$A22,tbConsumo[Tipo_Movimentacao],"Consumo") -> 10933 | E22: =IF(D$24=0,0,D22/D$24) -> 0.44431891
A23: =Parametros!$F$13 -> 2026-08 | B23: =COUNTIFS(tbConsumo[Mes],$A23,tbConsumo[Tipo_Movimentacao],"Consumo") -> 40 | C23: =SUMIFS(tbConsumo[Quantidade],tbConsumo[Mes],$A23,tbConsumo[Tipo_Movimentacao],"Consumo") -> 348 | D23: =SUMIFS(tbConsumo[Custo_Movimentado],tbConsumo[Mes],$A23,tbConsumo[Tipo_Movimentacao],"Consumo") -> 5217.1 | E23: =IF(D$24=0,0,D23/D$24) -> 0.2120238
A24: Total | B24: =SUM(B21:B23) -> 180 | C24: =SUM(C21:C23) -> 1647 | D24: =SUM(D21:D23) -> 24606.2 | E24: =SUM(E21:E23) -> 1
A26: 3. Resumo por categoria
A27: Categoria | B27: Movimentações | C27: Unidades consumidas | D27: Custo estimado | E27: % do custo
A28: =Parametros!$A$11 -> Abrasivos | B28: =COUNTIFS(tbConsumo[Categoria],$A28,tbConsumo[Tipo_Movimentacao],"Consumo") -> 38 | C28: =SUMIFS(tbConsumo[Quantidade],tbConsumo[Categoria],$A28,tbConsumo[Tipo_Movimentacao],"Consumo") -> 419 | D28: =SUMIFS(tbConsumo[Custo_Movimentado],tbConsumo[Categoria],$A28,tbConsumo[Tipo_Movimentacao],"Consumo") -> 4179.4 | E28: =IF(D$34=0,0,D28/D$34) -> 0.1698515
A29: =Parametros!$A$12 -> Soldagem | B29: =COUNTIFS(tbConsumo[Categoria],$A29,tbConsumo[Tipo_Movimentacao],"Consumo") -> 28 | C29: =SUMIFS(tbConsumo[Quantidade],tbConsumo[Categoria],$A29,tbConsumo[Tipo_Movimentacao],"Consumo") -> 57 | D29: =SUMIFS(tbConsumo[Custo_Movimentado],tbConsumo[Categoria],$A29,tbConsumo[Tipo_Movimentacao],"Consumo") -> 4869 | E29: =IF(D$34=0,0,D29/D$34) -> 0.19787696
A30: =Parametros!$A$13 -> Corte | B30: =COUNTIFS(tbConsumo[Categoria],$A30,tbConsumo[Tipo_Movimentacao],"Consumo") -> 43 | C30: =SUMIFS(tbConsumo[Quantidade],tbConsumo[Categoria],$A30,tbConsumo[Tipo_Movimentacao],"Consumo") -> 940 | D30: =SUMIFS(tbConsumo[Custo_Movimentado],tbConsumo[Categoria],$A30,tbConsumo[Tipo_Movimentacao],"Consumo") -> 7565.3 | E30: =IF(D$34=0,0,D30/D$34) -> 0.30745503
A31: =Parametros!$A$14 -> Elétrica | B31: =COUNTIFS(tbConsumo[Categoria],$A31,tbConsumo[Tipo_Movimentacao],"Consumo") -> 28 | C31: =SUMIFS(tbConsumo[Quantidade],tbConsumo[Categoria],$A31,tbConsumo[Tipo_Movimentacao],"Consumo") -> 45 | D31: =SUMIFS(tbConsumo[Custo_Movimentado],tbConsumo[Categoria],$A31,tbConsumo[Tipo_Movimentacao],"Consumo") -> 4871 | E31: =IF(D$34=0,0,D31/D$34) -> 0.19795824
A32: =Parametros!$A$15 -> EPI | B32: =COUNTIFS(tbConsumo[Categoria],$A32,tbConsumo[Tipo_Movimentacao],"Consumo") -> 34 | C32: =SUMIFS(tbConsumo[Quantidade],tbConsumo[Categoria],$A32,tbConsumo[Tipo_Movimentacao],"Consumo") -> 169 | D32: =SUMIFS(tbConsumo[Custo_Movimentado],tbConsumo[Categoria],$A32,tbConsumo[Tipo_Movimentacao],"Consumo") -> 2751.5 | E32: =IF(D$34=0,0,D32/D$34) -> 0.11182141
A33: =Parametros!$A$16 -> Ferramentas | B33: =COUNTIFS(tbConsumo[Categoria],$A33,tbConsumo[Tipo_Movimentacao],"Consumo") -> 9 | C33: =SUMIFS(tbConsumo[Quantidade],tbConsumo[Categoria],$A33,tbConsumo[Tipo_Movimentacao],"Consumo") -> 17 | D33: =SUMIFS(tbConsumo[Custo_Movimentado],tbConsumo[Categoria],$A33,tbConsumo[Tipo_Movimentacao],"Consumo") -> 370 | E33: =IF(D$34=0,0,D33/D$34) -> 0.015036861
A34: Total | B34: =SUM(B28:B33) -> 180 | C34: =SUM(C28:C33) -> 1647 | D34: =SUM(D28:D33) -> 24606.2 | E34: =SUM(E28:E33) -> 1
A36: 4. Resumo por centro de trabalho
A37: Centro_Trabalho | B37: Movimentações | C37: Unidades consumidas | D37: Custo estimado | E37: % do custo
A38: =Parametros!$D$11 -> MANUTENCAO | B38: =COUNTIFS(tbConsumo[Centro_Trabalho],$A38,tbConsumo[Tipo_Movimentacao],"Consumo") -> 54 | C38: =SUMIFS(tbConsumo[Quantidade],tbConsumo[Centro_Trabalho],$A38,tbConsumo[Tipo_Movimentacao],"Consumo") -> 413 | D38: =SUMIFS(tbConsumo[Custo_Movimentado],tbConsumo[Centro_Trabalho],$A38,tbConsumo[Tipo_Movimentacao],"Consumo") -> 6402.2 | E38: =IF(D$43=0,0,D38/D$43) -> 0.26018646
A39: =Parametros!$D$12 -> SOLDAGEM | B39: =COUNTIFS(tbConsumo[Centro_Trabalho],$A39,tbConsumo[Tipo_Movimentacao],"Consumo") -> 42 | C39: =SUMIFS(tbConsumo[Quantidade],tbConsumo[Centro_Trabalho],$A39,tbConsumo[Tipo_Movimentacao],"Consumo") -> 388 | D39: =SUMIFS(tbConsumo[Custo_Movimentado],tbConsumo[Centro_Trabalho],$A39,tbConsumo[Tipo_Movimentacao],"Consumo") -> 5739.8 | E39: =IF(D$43=0,0,D39/D$43) -> 0.23326641
A40: =Parametros!$D$13 -> FABRICACAO | B40: =COUNTIFS(tbConsumo[Centro_Trabalho],$A40,tbConsumo[Tipo_Movimentacao],"Consumo") -> 32 | C40: =SUMIFS(tbConsumo[Quantidade],tbConsumo[Centro_Trabalho],$A40,tbConsumo[Tipo_Movimentacao],"Consumo") -> 384 | D40: =SUMIFS(tbConsumo[Custo_Movimentado],tbConsumo[Centro_Trabalho],$A40,tbConsumo[Tipo_Movimentacao],"Consumo") -> 4806.5 | E40: =IF(D$43=0,0,D40/D$43) -> 0.19533695
A41: =Parametros!$D$14 -> MECANICA | B41: =COUNTIFS(tbConsumo[Centro_Trabalho],$A41,tbConsumo[Tipo_Movimentacao],"Consumo") -> 30 | C41: =SUMIFS(tbConsumo[Quantidade],tbConsumo[Centro_Trabalho],$A41,tbConsumo[Tipo_Movimentacao],"Consumo") -> 423 | D41: =SUMIFS(tbConsumo[Custo_Movimentado],tbConsumo[Centro_Trabalho],$A41,tbConsumo[Tipo_Movimentacao],"Consumo") -> 3909.7 | E41: =IF(D$43=0,0,D41/D$43) -> 0.15889085
A42: =Parametros!$D$15 -> ELETRICA | B42: =COUNTIFS(tbConsumo[Centro_Trabalho],$A42,tbConsumo[Tipo_Movimentacao],"Consumo") -> 22 | C42: =SUMIFS(tbConsumo[Quantidade],tbConsumo[Centro_Trabalho],$A42,tbConsumo[Tipo_Movimentacao],"Consumo") -> 39 | D42: =SUMIFS(tbConsumo[Custo_Movimentado],tbConsumo[Centro_Trabalho],$A42,tbConsumo[Tipo_Movimentacao],"Consumo") -> 3748 | E42: =IF(D$43=0,0,D42/D$43) -> 0.15231933
A43: Total | B43: =SUM(B38:B42) -> 180 | C43: =SUM(C38:C42) -> 1647 | D43: =SUM(D38:D42) -> 24606.2 | E43: =SUM(E38:E42) -> 1
A45: 5. Resumo por material
A46: Material_ID | B46: Movimentações | C46: Unidades consumidas | D46: Custo estimado | E46: % do custo | F46: Material | G46: Categoria | H46: Criticidade | I46: Estoque_Atual | J46: Status_Estoque
A47: =Materiais!$A$2 -> MAT001 | B47: =COUNTIFS(tbConsumo[Material_ID],$A47,tbConsumo[Tipo_Movimentacao],"Consumo") -> 13 | C47: =SUMIFS(tbConsumo[Quantidade],tbConsumo[Material_ID],$A47,tbConsumo[Tipo_Movimentacao],"Consumo") -> 169 | D47: =SUMIFS(tbConsumo[Custo_Movimentado],tbConsumo[Material_ID],$A47,tbConsumo[Tipo_Movimentacao],"Consumo") -> 1656.2 | E47: =IF(D$67=0,0,D47/D$67) -> 0.067308239 | F47: =IFERROR(INDEX(tbMateriais[Material],MATCH($A47,tbMateriais[Material_ID],0)),"Não encontrado") -> Disco de Desbaste 7 pol | G47: =IFERROR(INDEX(tbMateriais[Categoria],MATCH($A47,tbMateriais[Material_ID],0)),"Não encontrado") -> Abrasivos | H47: =IFERROR(INDEX(tbMateriais[Criticidade],MATCH($A47,tbMateriais[Material_ID],0)),"Não encontrado") -> Média | I47: =IFERROR(INDEX(tbEstoque[Estoque_Atual],MATCH($A47,tbEstoque[Material_ID],0)),"Sem estoque") -> 120 | J47: =IFERROR(INDEX(tbEstoque[Status_Estoque],MATCH($A47,tbEstoque[Material_ID],0)),"Sem estoque") -> OK
...

Sheet Analises
A1: Analises – camada de cálculo do DASHBOARD (V0.2)
A2: Dados 100% sintéticos utilizados exclusivamente para estudo e portfólio.
A3: Todas as células desta aba são fórmulas (nada digitado). Cadeia de rastreabilidade: tbConsumo/tbEstoque/tbMateriais -> Indicadores -> Analises -> DASHBOARD. Sem previsão: apenas soma, contagem, ordenação e percentuais do período observado.
A6: 1. Evolução mensal (lê Indicadores, seção 2)
A7: Mês (chave) | B7: Rótulo | C7: Movimentações | D7: Unidades consumidas | E7: Custo estimado | F7: Var. unidades vs mês anterior | G7: Var. custo vs mês anterior
A8: =Indicadores!A21 -> 2026-06 | B8: =CHOOSE(VALUE(RIGHT(A8,2)),"Jan","Fev","Mar","Abr","Mai","Jun","Jul","Ago","Set","Out","Nov","Dez")&"/"&LEFT(A8,4) -> Jun/2026 | C8: =Indicadores!B21 -> 65 | D8: =Indicadores!C21 -> 608 | E8: =Indicadores!D21 -> 8456.1 | F8: — | G8: —
A9: =Indicadores!A22 -> 2026-07 | B9: =CHOOSE(VALUE(RIGHT(A9,2)),"Jan","Fev","Mar","Abr","Mai","Jun","Jul","Ago","Set","Out","Nov","Dez")&"/"&LEFT(A9,4) -> Jul/2026 | C9: =Indicadores!B22 -> 75 | D9: =Indicadores!C22 -> 691 | E9: =Indicadores!D22 -> 10933 | F9: =IF(D8=0,"n/d",D9/D8-1) -> 0.13651316 | G9: =IF(E8=0,"n/d",E9/E8-1) -> 0.29291281
A10: =Indicadores!A23 -> 2026-08 | B10: =CHOOSE(VALUE(RIGHT(A10,2)),"Jan","Fev","Mar","Abr","Mai","Jun","Jul","Ago","Set","Out","Nov","Dez")&"/"&LEFT(A10,4) -> Ago/2026 | C10: =Indicadores!B23 -> 40 | D10: =Indicadores!C23 -> 348 | E10: =Indicadores!D23 -> 5217.1 | F10: =IF(D9=0,"n/d",D10/D9-1) -> -0.49638205 | G10: =IF(E9=0,"n/d",E10/E9-1) -> -0.52281167
A11: Total | C11: =SUM(C8:C10) -> 180 | D11: =SUM(D8:D10) -> 1647 | E11: =SUM(E8:E10) -> 24606.2
A14: 2. Categorias (lê Indicadores, seção 3)
A15: Categoria | B15: Movimentações | C15: Unidades consumidas | D15: Custo estimado | E15: % das unidades | F15: % do custo | G15: Posição (unidades) | H15: Posição (custo)
A16: =Indicadores!A28 -> Abrasivos | B16: =Indicadores!B28 -> 38 | C16: =Indicadores!C28 -> 419 | D16: =Indicadores!D28 -> 4179.4 | E16: =IF(Indicadores!$B$6=0,0,C16/Indicadores!$B$6) -> 0.25440194 | F16: =IF(Indicadores!$B$7=0,0,D16/Indicadores!$B$7) -> 0.1698515 | G16: =RANK(C16,C$16:C$21,0)+COUNTIF(C$16:C16,C16)-1 -> 2 | H16: =RANK(D16,D$16:D$21,0)+COUNTIF(D$16:D16,D16)-1 -> 4
A17: =Indicadores!A29 -> Soldagem | B17: =Indicadores!B29 -> 28 | C17: =Indicadores!C29 -> 57 | D17: =Indicadores!D29 -> 4869 | E17: =IF(Indicadores!$B$6=0,0,C17/Indicadores!$B$6) -> 0.034608379 | F17: =IF(Indicadores!$B$7=0,0,D17/Indicadores!$B$7) -> 0.19787696 | G17: =RANK(C17,C$16:C$21,0)+COUNTIF(C$16:C17,C17)-1 -> 4 | H17: =RANK(D17,D$16:D$21,0)+COUNTIF(D$16:D17,D17)-1 -> 3
A18: =Indicadores!A30 -> Corte | B18: =Indicadores!B30 -> 43 | C18: =Indicadores!C30 -> 940 | D18: =Indicadores!D30 -> 7565.3 | E18: =IF(Indicadores!$B$6=0,0,C18/Indicadores!$B$6) -> 0.57073467 | F18: =IF(Indicadores!$B$7=0,0,D18/Indicadores!$B$7) -> 0.30745503 | G18: =RANK(C18,C$16:C$21,0)+COUNTIF(C$16:C18,C18)-1 -> 1 | H18: =RANK(D18,D$16:D$21,0)+COUNTIF(D$16:D18,D18)-1 -> 1
A19: =Indicadores!A31 -> Elétrica | B19: =Indicadores!B31 -> 28 | C19: =Indicadores!C31 -> 45 | D19: =Indicadores!D31 -> 4871 | E19: =IF(Indicadores!$B$6=0,0,C19/Indicadores!$B$6) -> 0.027322404 | F19: =IF(Indicadores!$B$7=0,0,D19/Indicadores!$B$7) -> 0.19795824 | G19: =RANK(C19,C$16:C$21,0)+COUNTIF(C$16:C19,C19)-1 -> 5 | H19: =RANK(D19,D$16:D$21,0)+COUNTIF(D$16:D19,D19)-1 -> 2
A20: =Indicadores!A32 -> EPI | B20: =Indicadores!B32 -> 34 | C20: =Indicadores!C32 -> 169 | D20: =Indicadores!D32 -> 2751.5 | E20: =IF(Indicadores!$B$6=0,0,C20/Indicadores!$B$6) -> 0.10261081 | F20: =IF(Indicadores!$B$7=0,0,D20/Indicadores!$B$7) -> 0.11182141 | G20: =RANK(C20,C$16:C$21,0)+COUNTIF(C$16:C20,C20)-1 -> 3 | H20: =RANK(D20,D$16:D$21,0)+COUNTIF(D$16:D20,D20)-1 -> 5
A21: =Indicadores!A33 -> Ferramentas | B21: =Indicadores!B33 -> 9 | C21: =Indicadores!C33 -> 17 | D21: =Indicadores!D33 -> 370 | E21: =IF(Indicadores!$B$6=0,0,C21/Indicadores!$B$6) -> 0.010321797 | F21: =IF(Indicadores!$B$7=0,0,D21/Indicadores!$B$7) -> 0.015036861 | G21: =RANK(C21,C$16:C$21,0)+COUNTIF(C$16:C21,C21)-1 -> 6 | H21: =RANK(D21,D$16:D$21,0)+COUNTIF(D$16:D21,D21)-1 -> 6
A22: Total | B22: =SUM(B16:B21) -> 180 | C22: =SUM(C16:C21) -> 1647 | D22: =SUM(D16:D21) -> 24606.2 | E22: =SUM(E16:E21) -> 1 | F22: =SUM(F16:F21) -> 1
A24: Categorias ordenadas por unidades | F24: Categorias ordenadas por custo
A25: Posição | B25: Categoria | C25: Unidades consumidas | D25: % das unidades | F25: Posição | G25: Categoria | H25: Custo estimado | I25: % do custo
A26: =ROWS(A$26:A26) -> 1 | B26: =INDEX($A$16:$A$21,MATCH($A26,$G$16:$G$21,0)) -> Corte | C26: =INDEX($C$16:$C$21,MATCH($A26,$G$16:$G$21,0)) -> 940 | D26: =INDEX($E$16:$E$21,MATCH($A26,$G$16:$G$21,0)) -> 0.57073467 | F26: =ROWS(F$26:F26) -> 1 | G26: =INDEX($A$16:$A$21,MATCH($F26,$H$16:$H$21,0)) -> Corte | H26: =INDEX($D$16:$D$21,MATCH($F26,$H$16:$H$21,0)) -> 7565.3 | I26: =INDEX($F$16:$F$21,MATCH($F26,$H$16:$H$21,0)) -> 0.30745503
A27: =ROWS(A$26:A27) -> 2 | B27: =INDEX($A$16:$A$21,MATCH($A27,$G$16:$G$21,0)) -> Abrasivos | C27: =INDEX($C$16:$C$21,MATCH($A27,$G$16:$G$21,0)) -> 419 | D27: =INDEX($E$16:$E$21,MATCH($A27,$G$16:$G$21,0)) -> 0.25440194 | F27: =ROWS(F$26:F27) -> 2 | G27: =INDEX($A$16:$A$21,MATCH($F27,$H$16:$H$21,0)) -> Elétrica | H27: =INDEX($D$16:$D$21,MATCH($F27,$H$16:$H$21,0)) -> 4871 | I27: =INDEX($F$16:$F$21,MATCH($F27,$H$16:$H$21,0)) -> 0.19795824
A28: =ROWS(A$26:A28) -> 3 | B28: =INDEX($A$16:$A$21,MATCH($A28,$G$16:$G$21,0)) -> EPI | C28: =INDEX($C$16:$C$21,MATCH($A28,$G$16:$G$21,0)) -> 169 | D28: =INDEX($E$16:$E$21,MATCH($A28,$G$16:$G$21,0)) -> 0.10261081 | F28: =ROWS(F$26:F28) -> 3 | G28: =INDEX($A$16:$A$21,MATCH($F28,$H$16:$H$21,0)) -> Soldagem | H28: =INDEX($D$16:$D$21,MATCH($F28,$H$16:$H$21,0)) -> 4869 | I28: =INDEX($F$16:$F$21,MATCH($F28,$H$16:$H$21,0)) -> 0.19787696
A29: =ROWS(A$26:A29) -> 4 | B29: =INDEX($A$16:$A$21,MATCH($A29,$G$16:$G$21,0)) -> Soldagem | C29: =INDEX($C$16:$C$21,MATCH($A29,$G$16:$G$21,0)) -> 57 | D29: =INDEX($E$16:$E$21,MATCH($A29,$G$16:$G$21,0)) -> 0.034608379 | F29: =ROWS(F$26:F29) -> 4 | G29: =INDEX($A$16:$A$21,MATCH($F29,$H$16:$H$21,0)) -> Abrasivos | H29: =INDEX($D$16:$D$21,MATCH($F29,$H$16:$H$21,0)) -> 4179.4 | I29: =INDEX($F$16:$F$21,MATCH($F29,$H$16:$H$21,0)) -> 0.1698515
A30: =ROWS(A$26:A30) -> 5 | B30: =INDEX($A$16:$A$21,MATCH($A30,$G$16:$G$21,0)) -> Elétrica | C30: =INDEX($C$16:$C$21,MATCH($A30,$G$16:$G$21,0)) -> 45 | D30: =INDEX($E$16:$E$21,MATCH($A30,$G$16:$G$21,0)) -> 0.027322404 | F30: =ROWS(F$26:F30) -> 5 | G30: =INDEX($A$16:$A$21,MATCH($F30,$H$16:$H$21,0)) -> EPI | H30: =INDEX($D$16:$D$21,MATCH($F30,$H$16:$H$21,0)) -> 2751.5 | I30: =INDEX($F$16:$F$21,MATCH($F30,$H$16:$H$21,0)) -> 0.11182141
A31: =ROWS(A$26:A31) -> 6 | B31: =INDEX($A$16:$A$21,MATCH($A31,$G$16:$G$21,0)) -> Ferramentas | C31: =INDEX($C$16:$C$21,MATCH($A31,$G$16:$G$21,0)) -> 17 | D31: =INDEX($E$16:$E$21,MATCH($A31,$G$16:$G$21,0)) -> 0.010321797 | F31: =ROWS(F$26:F31) -> 6 | G31: =INDEX($A$16:$A$21,MATCH($F31,$H$16:$H$21,0)) -> Ferramentas | H31: =INDEX($D$16:$D$21,MATCH($F31,$H$16:$H$21,0)) -> 370 | I31: =INDEX($F$16:$F$21,MATCH($F31,$H$16:$H$21,0)) -> 0.015036861
A34: 3. Centros de trabalho (lê Indicadores, seção 4)
A35: Centro_Trabalho | B35: Movimentações | C35: Unidades consumidas | D35: Custo estimado | E35: % das unidades | F35: % do custo | G35: Posição (unidades) | H35: Posição (custo)
A36: =Indicadores!A38 -> MANUTENCAO | B36: =Indicadores!B38 -> 54 | C36: =Indicadores!C38 -> 413 | D36: =Indicadores!D38 -> 6402.2 | E36: =IF(Indicadores!$B$6=0,0,C36/Indicadores!$B$6) -> 0.25075896 | F36: =IF(Indicadores!$B$7=0,0,D36/Indicadores!$B$7) -> 0.26018646 | G36: =RANK(C36,C$36:C$40,0)+COUNTIF(C$36:C36,C36)-1 -> 2 | H36: =RANK(D36,D$36:D$40,0)+COUNTIF(D$36:D36,D36)-1 -> 1
A37: =Indicadores!A39 -> SOLDAGEM | B37: =Indicadores!B39 -> 42 | C37: =Indicadores!C39 -> 388 | D37: =Indicadores!D39 -> 5739.8 | E37: =IF(Indicadores!$B$6=0,0,C37/Indicadores!$B$6) -> 0.23557984 | F37: =IF(Indicadores!$B$7=0,0,D37/Indicadores!$B$7) -> 0.23326641 | G37: =RANK(C37,C$36:C$40,0)+COUNTIF(C$36:C37,C37)-1 -> 3 | H37: =RANK(D37,D$36:D$40,0)+COUNTIF(D$36:D37,D37)-1 -> 2
A38: =Indicadores!A40 -> FABRICACAO | B38: =Indicadores!B40 -> 32 | C38: =Indicadores!C40 -> 384 | D38: =Indicadores!D40 -> 4806.5 | E38: =IF(Indicadores!$B$6=0,0,C38/Indicadores!$B$6) -> 0.23315118 | F38: =IF(Indicadores!$B$7=0,0,D38/Indicadores!$B$7) -> 0.19533695 | G38: =RANK(C38,C$36:C$40,0)+COUNTIF(C$36:C38,C38)-1 -> 4 | H38: =RANK(D38,D$36:D$40,0)+COUNTIF(D$36:D38,D38)-1 -> 3
A39: =Indicadores!A41 -> MECANICA | B39: =Indicadores!B41 -> 30 | C39: =Indicadores!C41 -> 423 | D39: =Indicadores!D41 -> 3909.7 | E39: =IF(Indicadores!$B$6=0,0,C39/Indicadores!$B$6) -> 0.2568306 | F39: =IF(Indicadores!$B$7=0,0,D39/Indicadores!$B$7) -> 0.15889085 | G39: =RANK(C39,C$36:C$40,0)+COUNTIF(C$36:C39,C39)-1 -> 1 | H39: =RANK(D39,D$36:D$40,0)+COUNTIF(D$36:D39,D39)-1 -> 4
A40: =Indicadores!A42 -> ELETRICA | B40: =Indicadores!B42 -> 22 | C40: =Indicadores!C42 -> 39 | D40: =Indicadores!D42 -> 3748 | E40: =IF(Indicadores!$B$6=0,0,C40/Indicadores!$B$6) -> 0.023679417 | F40: =IF(Indicadores!$B$7=0,0,D40/Indicadores!$B$7) -> 0.15231933 | G40: =RANK(C40,C$36:C$40,0)+COUNTIF(C$36:C40,C40)-1 -> 5 | H40: =RANK(D40,D$36:D$40,0)+COUNTIF(D$36:D40,D40)-1 -> 5
A41: Total | B41: =SUM(B36:B40) -> 180 | C41: =SUM(C36:C40) -> 1647 | D41: =SUM(D36:D40) -> 24606.2 | E41: =SUM(E36:E40) -> 1 | F41: =SUM(F36:F40) -> 1
A43: Centros ordenados por unidades | F43: Centros ordenados por custo
A44: Posição | B44: Centro_Trabalho | C44: Unidades consumidas | D44: % das unidades | F44: Posição | G44: Centro_Trabalho | H44: Custo estimado | I44: % do custo
A45: =ROWS(A$45:A45) -> 1 | B45: =INDEX($A$36:$A$40,MATCH($A45,$G$36:$G$40,0)) -> MECANICA | C45: =INDEX($C$36:$C$40,MATCH($A45,$G$36:$G$40,0)) -> 423 | D45: =INDEX($E$36:$E$40,MATCH($A45,$G$36:$G$40,0)) -> 0.2568306 | F45: =ROWS(F$45:F45) -> 1 | G45: =INDEX($A$36:$A$40,MATCH($F45,$H$36:$H$40,0)) -> MANUTENCAO | H45: =INDEX($D$36:$D$40,MATCH($F45,$H$36:$H$40,0)) -> 6402.2 | I45: =INDEX($F$36:$F$40,MATCH($F45,$H$36:$H$40,0)) -> 0.26018646
A46: =ROWS(A$45:A46) -> 2 | B46: =INDEX($A$36:$A$40,MATCH($A46,$G$36:$G$40,0)) -> MANUTENCAO | C46: =INDEX($C$36:$C$40,MATCH($A46,$G$36:$G$40,0)) -> 413 | D46: =INDEX($E$36:$E$40,MATCH($A46,$G$36:$G$40,0)) -> 0.25075896 | F46: =ROWS(F$45:F46) -> 2 | G46: =INDEX($A$36:$A$40,MATCH($F46,$H$36:$H$40,0)) -> SOLDAGEM | H46: =INDEX($D$36:$D$40,MATCH($F46,$H$36:$H$40,0)) -> 5739.8 | I46: =INDEX($F$36:$F$40,MATCH($F46,$H$36:$H$40,0)) -> 0.23326641
A47: =ROWS(A$45:A47) -> 3 | B47: =INDEX($A$36:$A$40,MATCH($A47,$G$36:$G$40,0)) -> SOLDAGEM | C47: =INDEX($C$36:$C$40,MATCH($A47,$G$36:$G$40,0)) -> 388 | D47: =INDEX($E$36:$E$40,MATCH($A47,$G$36:$G$40,0)) -> 0.23557984 | F47: =ROWS(F$45:F47) -> 3 | G47: =INDEX($A$36:$A$40,MATCH($F47,$H$36:$H$40,0)) -> FABRICACAO | H47: =INDEX($D$36:$D$40,MATCH($F47,$H$36:$H$40,0)) -> 4806.5 | I47: =INDEX($F$36:$F$40,MATCH($F47,$H$36:$H$40,0)) -> 0.19533695
A48: =ROWS(A$45:A48) -> 4 | B48: =INDEX($A$36:$A$40,MATCH($A48,$G$36:$G$40,0)) -> FABRICACAO | C48: =INDEX($C$36:$C$40,MATCH($A48,$G$36:$G$40,0)) -> 384 | D48: =INDEX($E$36:$E$40,MATCH($A48,$G$36:$G$40,0)) -> 0.23315118 | F48: =ROWS(F$45:F48) -> 4 | G48: =INDEX($A$36:$A$40,MATCH($F48,$H$36:$H$40,0)) -> MECANICA | H48: =INDEX($D$36:$D$40,MATCH($F48,$H$36:$H$40,0)) -> 3909.7 | I48: =INDEX($F$36:$F$40,MATCH($F48,$H$36:$H$40,0)) -> 0.15889085
...

Sheet Materiais
A1: Material_ID | B1: Material | C1: Categoria | D1: Unidade | E1: Custo_Unitario | F1: Criticidade | G1: Fornecedor
A2: MAT001 | B2: Disco de Desbaste 7 pol | C2: Abrasivos | D2: UN | E2: 9.8 | F2: Média | G2: Fornecedor Beta
A3: MAT002 | B3: Disco Flap 4,5 pol Grão 60 | C3: Abrasivos | D3: UN | E3: 7.4 | F3: Baixa | G3: Fornecedor Beta
A4: MAT003 | B4: Lixa de Ferro Grão 80 | C4: Abrasivos | D4: PCT | E4: 38 | F4: Baixa | G4: Fornecedor Gama
A5: MAT004 | B5: Bico de Contato MIG 1,0 mm | C5: Soldagem | D5: PCT | E5: 45 | F5: Média | G5: Fornecedor Delta
A6: MAT005 | B6: Eletrodo Revestido 2,5 mm | C6: Soldagem | D6: CX | E6: 96 | F6: Alta | G6: Fornecedor Alfa
A7: MAT006 | B7: Arame MIG 1,0 mm Bobina | C7: Soldagem | D7: UN | E7: 210 | F7: Alta | G7: Fornecedor Delta
A8: MAT007 | B8: Disco de Corte 7 pol | C8: Corte | D8: UN | E8: 12.5 | F8: Alta | G8: Fornecedor Alfa
A9: MAT008 | B9: Disco de Corte 4,5 pol | C9: Corte | D9: UN | E9: 5.9 | F9: Média | G9: Fornecedor Alfa
A10: MAT009 | B10: Serra Copo 51 mm | C10: Corte | D10: UN | E10: 46 | F10: Baixa | G10: Fornecedor Sigma
A11: MAT010 | B11: Lâmina de Serra Sabre | C11: Corte | D11: PCT | E11: 62 | F11: Média | G11: Fornecedor Sigma
A12: MAT011 | B12: Cabo Flexível 2,5 mm² Rolo | C12: Elétrica | D12: UN | E12: 285 | F12: Média | G12: Fornecedor Beta
A13: MAT012 | B13: Fita Isolante 19 mm | C13: Elétrica | D13: PCT | E13: 42 | F13: Baixa | G13: Fornecedor Gama
... A21: MAT020 | B21: Broca de Aço Rápido 10 mm | C21: Ferramentas | D21: UN | E21: 21 | F21: Média | G21: Fornecedor Alfa

Sheet Estoque
A1: Material_ID | B1: Material | C1: Categoria | D1: Unidade | E1: Estoque_Atual | F1: Estoque_Minimo | G1: Custo_Unitario | H1: Lead_Time_Dias | I1: Fornecedor | J1: Criticidade | K1: Status_Estoque | L1: Critico_Em_Risco
A2: MAT001 | B2: Disco de Desbaste 7 pol | C2: Abrasivos | D2: UN | E2: 120 | F2: 40 | G2: 9.8 | H2: 7 | I2: Fornecedor Beta | J2: Média | K2: =IF(tbEstoque[[#This Row],[Estoque_Atual]]<=tbEstoque[[#This Row],[Estoque_Minimo]],"REPOR",IF(tbEstoque[[#This Row],[Estoque_Atual]]<=tbEstoque[[#This Row],[Estoque_Minimo]]*(1+pMargemAtencao),"ATENÇÃO","OK")) -> OK | L2: =IF(AND(tbEstoque[[#This Row],[Criticidade]]="Alta",tbEstoque[[#This Row],[Status_Estoque]]="REPOR"),"Sim","Não") -> Não
A3: MAT002 | B3: Disco Flap 4,5 pol Grão 60 | C3: Abrasivos | D3: UN | E3: 30 | F3: 30 | G3: 7.4 | H3: 7 | I3: Fornecedor Beta | J3: Baixa | K3: =IF(tbEstoque[[#This Row],[Estoque_Atual]]<=tbEstoque[[#This Row],[Estoque_Minimo]],"REPOR",IF(tbEstoque[[#This Row],[Estoque_Atual]]<=tbEstoque[[#This Row],[Estoque_Minimo]]*(1+pMargemAtencao),"ATENÇÃO","OK")) -> REPOR | L3: =IF(AND(tbEstoque[[#This Row],[Criticidade]]="Alta",tbEstoque[[#This Row],[Status_Estoque]]="REPOR"),"Sim","Não") -> Não
A4: MAT003 | B4: Lixa de Ferro Grão 80 | C4: Abrasivos | D4: PCT | E4: 34 | F4: 10 | G4: 38 | H4: 10 | I4: Fornecedor Gama | J4: Baixa | K4: =IF(tbEstoque[[#This Row],[Estoque_Atual]]<=tbEstoque[[#This Row],[Estoque_Minimo]],"REPOR",IF(tbEstoque[[#This Row],[Estoque_Atual]]<=tbEstoque[[#This Row],[Estoque_Minimo]]*(1+pMargemAtencao),"ATENÇÃO","OK")) -> OK | L4: =IF(AND(tbEstoque[[#This Row],[Criticidade]]="Alta",tbEstoque[[#This Row],[Status_Estoque]]="REPOR"),"Sim","Não") -> Não
A5: MAT004 | B5: Bico de Contato MIG 1,0 mm | C5: Soldagem | D5: PCT | E5: 9 | F5: 8 | G5: 45 | H5: 14 | I5: Fornecedor Delta | J5: Média | K5: =IF(tbEstoque[[#This Row],[Estoque_Atual]]<=tbEstoque[[#This Row],[Estoque_Minimo]],"REPOR",IF(tbEstoque[[#This Row],[Estoque_Atual]]<=tbEstoque[[#This Row],[Estoque_Minimo]]*(1+pMargemAtencao),"ATENÇÃO","OK")) -> ATENÇÃO | L5: =IF(AND(tbEstoque[[#This Row],[Criticidade]]="Alta",tbEstoque[[#This Row],[Status_Estoque]]="REPOR"),"Sim","Não") -> Não
A6: MAT005 | B6: Eletrodo Revestido 2,5 mm | C6: Soldagem | D6: CX | E6: 7 | F6: 12 | G6: 96 | H6: 12 | I6: Fornecedor Alfa | J6: Alta | K6: =IF(tbEstoque[[#This Row],[Estoque_Atual]]<=tbEstoque[[#This Row],[Estoque_Minimo]],"REPOR",IF(tbEstoque[[#This Row],[Estoque_Atual]]<=tbEstoque[[#This Row],[Estoque_Minimo]]*(1+pMargemAtencao),"ATENÇÃO","OK")) -> REPOR | L6: =IF(AND(tbEstoque[[#This Row],[Criticidade]]="Alta",tbEstoque[[#This Row],[Status_Estoque]]="REPOR"),"Sim","Não") -> Sim
A7: MAT006 | B7: Arame MIG 1,0 mm Bobina | C7: Soldagem | D7: UN | E7: 14 | F7: 6 | G7: 210 | H7: 21 | I7: Fornecedor Delta | J7: Alta | K7: =IF(tbEstoque[[#This Row],[Estoque_Atual]]<=tbEstoque[[#This Row],[Estoque_Minimo]],"REPOR",IF(tbEstoque[[#This Row],[Estoque_Atual]]<=tbEstoque[[#This Row],[Estoque_Minimo]]*(1+pMargemAtencao),"ATENÇÃO","OK")) -> OK | L7: =IF(AND(tbEstoque[[#This Row],[Criticidade]]="Alta",tbEstoque[[#This Row],[Status_Estoque]]="REPOR"),"Sim","Não") -> Não
A8: MAT007 | B8: Disco de Corte 7 pol | C8: Corte | D8: UN | E8: 74 | F8: 60 | G8: 12.5 | H8: 7 | I8: Fornecedor Alfa | J8: Alta | K8: =IF(tbEstoque[[#This Row],[Estoque_Atual]]<=tbEstoque[[#This Row],[Estoque_Minimo]],"REPOR",IF(tbEstoque[[#This Row],[Estoque_Atual]]<=tbEstoque[[#This Row],[Estoque_Minimo]]*(1+pMargemAtencao),"ATENÇÃO","OK")) -> ATENÇÃO | L8: =IF(AND(tbEstoque[[#This Row],[Criticidade]]="Alta",tbEstoque[[#This Row],[Status_Estoque]]="REPOR"),"Sim","Não") -> Não
A9: MAT008 | B9: Disco de Corte 4,5 pol | C9: Corte | D9: UN | E9: 210 | F9: 80 | G9: 5.9 | H9: 7 | I9: Fornecedor Alfa | J9: Média | K9: =IF(tbEstoque[[#This Row],[Estoque_Atual]]<=tbEstoque[[#This Row],[Estoque_Minimo]],"REPOR",IF(tbEstoque[[#This Row],[Estoque_Atual]]<=tbEstoque[[#This Row],[Estoque_Minimo]]*(1+pMargemAtencao),"ATENÇÃO","OK")) -> OK | L9: =IF(AND(tbEstoque[[#This Row],[Criticidade]]="Alta",tbEstoque[[#This Row],[Status_Estoque]]="REPOR"),"Sim","Não") -> Não
A10: MAT009 | B10: Serra Copo 51 mm | C10: Corte | D10: UN | E10: 12 | F10: 4 | G10: 46 | H10: 15 | I10: Fornecedor Sigma | J10: Baixa | K10: =IF(tbEstoque[[#This Row],[Estoque_Atual]]<=tbEstoque[[#This Row],[Estoque_Minimo]],"REPOR",IF(tbEstoque[[#This Row],[Estoque_Atual]]<=tbEstoque[[#This Row],[Estoque_Minimo]]*(1+pMargemAtencao),"ATENÇÃO","OK")) -> OK | L10: =IF(AND(tbEstoque[[#This Row],[Criticidade]]="Alta",tbEstoque[[#This Row],[Status_Estoque]]="REPOR"),"Sim","Não") -> Não
A11: MAT010 | B11: Lâmina de Serra Sabre | C11: Corte | D11: PCT | E11: 5 | F11: 6 | G11: 62 | H11: 18 | I11: Fornecedor Sigma | J11: Média | K11: =IF(tbEstoque[[#This Row],[Estoque_Atual]]<=tbEstoque[[#This Row],[Estoque_Minimo]],"REPOR",IF(tbEstoque[[#This Row],[Estoque_Atual]]<=tbEstoque[[#This Row],[Estoque_Minimo]]*(1+pMargemAtencao),"ATENÇÃO","OK")) -> REPOR | L11: =IF(AND(tbEstoque[[#This Row],[Criticidade]]="Alta",tbEstoque[[#This Row],[Status_Estoque]]="REPOR"),"Sim","Não") -> Não
A12: MAT011 | B12: Cabo Flexível 2,5 mm² Rolo | C12: Elétrica | D12: UN | E12: 8 | F12: 3 | G12: 285 | H12: 20 | I12: Fornecedor Beta | J12: Média | K12: =IF(tbEstoque[[#This Row],[Estoque_Atual]]<=tbEstoque[[#This Row],[Estoque_Minimo]],"REPOR",IF(tbEstoque[[#This Row],[Estoque_Atual]]<=tbEstoque[[#This Row],[Estoque_Minimo]]*(1+pMargemAtencao),"ATENÇÃO","OK")) -> OK | L12: =IF(AND(tbEstoque[[#This Row],[Criticidade]]="Alta",tbEstoque[[#This Row],[Status_Estoque]]="REPOR"),"Sim","Não") -> Não
A13: MAT012 | B13: Fita Isolante 19 mm | C13: Elétrica | D13: PCT | E13: 25 | F13: 10 | G13: 42 | H13: 10 | I13: Fornecedor Gama | J13: Baixa | K13: =IF(tbEstoque[[#This Row],[Estoque_Atual]]<=tbEstoque[[#This Row],[Estoque_Minimo]],"REPOR",IF(tbEstoque[[#This Row],[Estoque_Atual]]<=tbEstoque[[#This Row],[Estoque_Minimo]]*(1+pMargemAtencao),"ATENÇÃO","OK")) -> OK | L13: =IF(AND(tbEstoque[[#This Row],[Criticidade]]="Alta",tbEstoque[[#This Row],[Status_Estoque]]="REPOR"),"Sim","Não") -> Não
... A21: MAT020 | B21: Broca de Aço Rápido 10 mm | C21: Ferramentas | D21: UN | E21: 26 | F21: 10 | G21: 21 | H21: 12 | I21: Fornecedor Alfa | J21: Média | K21: =IF(tbEstoque[[#This Row],[Estoque_Atual]]<=tbEstoque[[#This Row],[Estoque_Minimo]],"REPOR",IF(tbEstoque[[#This Row],[Estoque_Atual]]<=tbEstoque[[#This Row],[Estoque_Minimo]]*(1+pMargemAtencao),"ATENÇÃO","OK")) -> OK | L21: =IF(AND(tbEstoque[[#This Row],[Criticidade]]="Alta",tbEstoque[[#This Row],[Status_Estoque]]="REPOR"),"Sim","Não") -> Não

Sheet Consumo
A1: Movimento_ID | B1: Data | C1: Material_ID | D1: Material | E1: Categoria | F1: Quantidade | G1: Unidade | H1: Custo_Unitario | I1: Centro_Trabalho | J1: Tipo_Movimentacao | K1: Custo_Movimentado | L1: Mes
A2: MOV0001 | B2: 46174 | C2: MAT004 | D2: Bico de Contato MIG 1,0 mm | E2: Soldagem | F2: 2 | G2: PCT | H2: 45 | I2: SOLDAGEM | J2: Consumo | K2: =ROUND(tbConsumo[[#This Row],[Quantidade]]*tbConsumo[[#This Row],[Custo_Unitario]],2) -> 90 | L2: =YEAR(tbConsumo[[#This Row],[Data]])&"-"&TEXT(MONTH(tbConsumo[[#This Row],[Data]]),"00") -> 2026-06
A3: MOV0002 | B3: 46175 | C3: MAT020 | D3: Broca de Aço Rápido 10 mm | E3: Ferramentas | F3: 1 | G3: UN | H3: 21 | I3: ELETRICA | J3: Consumo | K3: =ROUND(tbConsumo[[#This Row],[Quantidade]]*tbConsumo[[#This Row],[Custo_Unitario]],2) -> 21 | L3: =YEAR(tbConsumo[[#This Row],[Data]])&"-"&TEXT(MONTH(tbConsumo[[#This Row],[Data]]),"00") -> 2026-06
A4: MOV0003 | B4: 46176 | C4: MAT018 | D4: Chave Combinada 17 mm | E4: Ferramentas | F4: 2 | G4: UN | H4: 24 | I4: MANUTENCAO | J4: Consumo | K4: =ROUND(tbConsumo[[#This Row],[Quantidade]]*tbConsumo[[#This Row],[Custo_Unitario]],2) -> 48 | L4: =YEAR(tbConsumo[[#This Row],[Data]])&"-"&TEXT(MONTH(tbConsumo[[#This Row],[Data]]),"00") -> 2026-06
A5: MOV0004 | B5: 46176 | C5: MAT018 | D5: Chave Combinada 17 mm | E5: Ferramentas | F5: 1 | G5: UN | H5: 24 | I5: MANUTENCAO | J5: Consumo | K5: =ROUND(tbConsumo[[#This Row],[Quantidade]]*tbConsumo[[#This Row],[Custo_Unitario]],2) -> 24 | L5: =YEAR(tbConsumo[[#This Row],[Data]])&"-"&TEXT(MONTH(tbConsumo[[#This Row],[Data]]),"00") -> 2026-06
A6: MOV0005 | B6: 46176 | C6: MAT001 | D6: Disco de Desbaste 7 pol | E6: Abrasivos | F6: 10 | G6: UN | H6: 9.8 | I6: MANUTENCAO | J6: Consumo | K6: =ROUND(tbConsumo[[#This Row],[Quantidade]]*tbConsumo[[#This Row],[Custo_Unitario]],2) -> 98 | L6: =YEAR(tbConsumo[[#This Row],[Data]])&"-"&TEXT(MONTH(tbConsumo[[#This Row],[Data]]),"00") -> 2026-06
A7: MOV0006 | B7: 46177 | C7: MAT003 | D7: Lixa de Ferro Grão 80 | E7: Abrasivos | F7: 1 | G7: PCT | H7: 38 | I7: SOLDAGEM | J7: Consumo | K7: =ROUND(tbConsumo[[#This Row],[Quantidade]]*tbConsumo[[#This Row],[Custo_Unitario]],2) -> 38 | L7: =YEAR(tbConsumo[[#This Row],[Data]])&"-"&TEXT(MONTH(tbConsumo[[#This Row],[Data]]),"00") -> 2026-06
A8: MOV0007 | B8: 46177 | C8: MAT012 | D8: Fita Isolante 19 mm | E8: Elétrica | F8: 2 | G8: PCT | H8: 42 | I8: ELETRICA | J8: Consumo | K8: =ROUND(tbConsumo[[#This Row],[Quantidade]]*tbConsumo[[#This Row],[Custo_Unitario]],2) -> 84 | L8: =YEAR(tbConsumo[[#This Row],[Data]])&"-"&TEXT(MONTH(tbConsumo[[#This Row],[Data]]),"00") -> 2026-06
A9: MOV0008 | B9: 46177 | C9: MAT001 | D9: Disco de Desbaste 7 pol | E9: Abrasivos | F9: 15 | G9: UN | H9: 9.8 | I9: MANUTENCAO | J9: Consumo | K9: =ROUND(tbConsumo[[#This Row],[Quantidade]]*tbConsumo[[#This Row],[Custo_Unitario]],2) -> 147 | L9: =YEAR(tbConsumo[[#This Row],[Data]])&"-"&TEXT(MONTH(tbConsumo[[#This Row],[Data]]),"00") -> 2026-06
A10: MOV0009 | B10: 46177 | C10: MAT018 | D10: Chave Combinada 17 mm | E10: Ferramentas | F10: 2 | G10: UN | H10: 24 | I10: MANUTENCAO | J10: Consumo | K10: =ROUND(tbConsumo[[#This Row],[Quantidade]]*tbConsumo[[#This Row],[Custo_Unitario]],2) -> 48 | L10: =YEAR(tbConsumo[[#This Row],[Data]])&"-"&TEXT(MONTH(tbConsumo[[#This Row],[Data]]),"00") -> 2026-06
A11: MOV0010 | B11: 46177 | C11: MAT017 | D11: Máscara Respiratória PFF2 | E11: EPI | F11: 3 | G11: CX | H11: 72 | I11: FABRICACAO | J11: Consumo | K11: =ROUND(tbConsumo[[#This Row],[Quantidade]]*tbConsumo[[#This Row],[Custo_Unitario]],2) -> 216 | L11: =YEAR(tbConsumo[[#This Row],[Data]])&"-"&TEXT(MONTH(tbConsumo[[#This Row],[Data]]),"00") -> 2026-06
A12: MOV0011 | B12: 46178 | C12: MAT011 | D12: Cabo Flexível 2,5 mm² Rolo | E12: Elétrica | F12: 1 | G12: UN | H12: 285 | I12: FABRICACAO | J12: Consumo | K12: =ROUND(tbConsumo[[#This Row],[Quantidade]]*tbConsumo[[#This Row],[Custo_Unitario]],2) -> 285 | L12: =YEAR(tbConsumo[[#This Row],[Data]])&"-"&TEXT(MONTH(tbConsumo[[#This Row],[Data]]),"00") -> 2026-06
A13: MOV0012 | B13: 46178 | C13: MAT004 | D13: Bico de Contato MIG 1,0 mm | E13: Soldagem | F13: 2 | G13: PCT | H13: 45 | I13: MECANICA | J13: Consumo | K13: =ROUND(tbConsumo[[#This Row],[Quantidade]]*tbConsumo[[#This Row],[Custo_Unitario]],2) -> 90 | L13: =YEAR(tbConsumo[[#This Row],[Data]])&"-"&TEXT(MONTH(tbConsumo[[#This Row],[Data]]),"00") -> 2026-06
... A181: MOV0180 | B181: 46265 | C181: MAT007 | D181: Disco de Corte 7 pol | E181: Corte | F181: 12 | G181: UN | H181: 12.5 | I181: MECANICA | J181: Consumo | K181: =ROUND(tbConsumo[[#This Row],[Quantidade]]*tbConsumo[[#This Row],[Custo_Unitario]],2) -> 150 | L181: =YEAR(tbConsumo[[#This Row],[Data]])&"-"&TEXT(MONTH(tbConsumo[[#This Row],[Data]]),"00") -> 2026-08

Sheet Qualidade
A1: Qualidade dos dados – verificações ao vivo (fórmulas)
A2: Dados 100% sintéticos utilizados exclusivamente para estudo e portfólio.
A3: Cada linha é uma fórmula sobre tbMateriais, tbEstoque e tbConsumo. Erros = 0 => PASS. O mesmo conjunto (Q01–Q36) é executado de forma independente em Python (scripts/validar_dados.py).
A5: Testes executados | B5: =COUNTA(A10:A45) -> 36
A6: PASS | B6: =COUNTIF(E10:E45,"PASS") -> 36
A7: FAIL | B7: =COUNTIF(E10:E45,"FAIL") -> 0
A9: Teste | B9: Regra | C9: Resultado | D9: Quantidade de erros | E9: Status
A10: Q01 · IDs duplicados – Materiais | B10: Material_ID não se repete (conta linhas envolvidas em duplicidade) | C10: =IF(D10=0,"Nenhum erro encontrado","Erros encontrados") -> Nenhum erro encontrado | D10: =SUMPRODUCT(--(COUNTIF(tbMateriais[Material_ID],tbMateriais[Material_ID])>1)) -> 0 | E10: =IF(D10=0,"PASS","FAIL") -> PASS
A11: Q02 · IDs duplicados – Estoque | B11: Material_ID não se repete na posição de estoque | C11: =IF(D11=0,"Nenhum erro encontrado","Erros encontrados") -> Nenhum erro encontrado | D11: =SUMPRODUCT(--(COUNTIF(tbEstoque[Material_ID],tbEstoque[Material_ID])>1)) -> 0 | E11: =IF(D11=0,"PASS","FAIL") -> PASS
A12: Q03 · IDs duplicados – Consumo | B12: Movimento_ID não se repete | C12: =IF(D12=0,"Nenhum erro encontrado","Erros encontrados") -> Nenhum erro encontrado | D12: =SUMPRODUCT(--(COUNTIF(tbConsumo[Movimento_ID],tbConsumo[Movimento_ID])>1)) -> 0 | E12: =IF(D12=0,"PASS","FAIL") -> PASS
A13: Q04 · Nulos indevidos – Materiais | B13: Nenhuma célula vazia na tabela | C13: =IF(D13=0,"Nenhum erro encontrado","Erros encontrados") -> Nenhum erro encontrado | D13: =COUNTBLANK(tbMateriais) -> 0 | E13: =IF(D13=0,"PASS","FAIL") -> PASS
A14: Q05 · Nulos indevidos – Estoque | B14: Nenhuma célula vazia na tabela | C14: =IF(D14=0,"Nenhum erro encontrado","Erros encontrados") -> Nenhum erro encontrado | D14: =COUNTBLANK(tbEstoque) -> 0 | E14: =IF(D14=0,"PASS","FAIL") -> PASS
A15: Q06 · Nulos indevidos – Consumo | B15: Nenhuma célula vazia na tabela | C15: =IF(D15=0,"Nenhum erro encontrado","Erros encontrados") -> Nenhum erro encontrado | D15: =COUNTBLANK(tbConsumo) -> 0 | E15: =IF(D15=0,"PASS","FAIL") -> PASS
A16: Q07 · Quantidade inválida – Consumo | B16: Quantidade numérica, inteira e > 0 | C16: =IF(D16=0,"Nenhum erro encontrado","Erros encontrados") -> Nenhum erro encontrado | D16: =IF(ROWS(tbConsumo[Quantidade])-COUNT(tbConsumo[Quantidade])>0,ROWS(tbConsumo[Quantidade])-COUNT(tbConsumo[Quantidade]),COUNTIF(tbConsumo[Quantidade],"<=0")+SUMPRODUCT(--(tbConsumo[Quantidade]<>INT(tbConsumo[Quantidade])))) -> 0 | E16: =IF(D16=0,"PASS","FAIL") -> PASS
A17: Q08 · Custo <= 0 – Materiais | B17: Custo_Unitario numérico e > 0 | C17: =IF(D17=0,"Nenhum erro encontrado","Erros encontrados") -> Nenhum erro encontrado | D17: =IF(ROWS(tbMateriais[Custo_Unitario])-COUNT(tbMateriais[Custo_Unitario])>0,ROWS(tbMateriais[Custo_Unitario])-COUNT(tbMateriais[Custo_Unitario]),COUNTIF(tbMateriais[Custo_Unitario],"<=0")) -> 0 | E17: =IF(D17=0,"PASS","FAIL") -> PASS
A18: Q09 · Custo <= 0 – Estoque | B18: Custo_Unitario numérico e > 0 | C18: =IF(D18=0,"Nenhum erro encontrado","Erros encontrados") -> Nenhum erro encontrado | D18: =IF(ROWS(tbEstoque[Custo_Unitario])-COUNT(tbEstoque[Custo_Unitario])>0,ROWS(tbEstoque[Custo_Unitario])-COUNT(tbEstoque[Custo_Unitario]),COUNTIF(tbEstoque[Custo_Unitario],"<=0")) -> 0 | E18: =IF(D18=0,"PASS","FAIL") -> PASS
A19: Q10 · Custo <= 0 – Consumo | B19: Custo_Unitario numérico e > 0 | C19: =IF(D19=0,"Nenhum erro encontrado","Erros encontrados") -> Nenhum erro encontrado | D19: =IF(ROWS(tbConsumo[Custo_Unitario])-COUNT(tbConsumo[Custo_Unitario])>0,ROWS(tbConsumo[Custo_Unitario])-COUNT(tbConsumo[Custo_Unitario]),COUNTIF(tbConsumo[Custo_Unitario],"<=0")) -> 0 | E19: =IF(D19=0,"PASS","FAIL") -> PASS
A20: Q11 · Material inexistente – Estoque | B20: Material_ID do estoque existe no catálogo | C20: =IF(D20=0,"Nenhum erro encontrado","Erros encontrados") -> Nenhum erro encontrado | D20: =SUMPRODUCT(--(COUNTIF(tbMateriais[Material_ID],tbEstoque[Material_ID])=0)) -> 0 | E20: =IF(D20=0,"PASS","FAIL") -> PASS
A21: Q12 · Material inexistente – Consumo | B21: Material_ID do consumo existe no catálogo | C21: =IF(D21=0,"Nenhum erro encontrado","Erros encontrados") -> Nenhum erro encontrado | D21: =SUMPRODUCT(--(COUNTIF(tbMateriais[Material_ID],tbConsumo[Material_ID])=0)) -> 0 | E21: =IF(D21=0,"PASS","FAIL") -> PASS
A22: Q13 · Catálogo sem estoque | B22: Todo material do catálogo tem posição de estoque | C22: =IF(D22=0,"Nenhum erro encontrado","Erros encontrados") -> Nenhum erro encontrado | D22: =SUMPRODUCT(--(COUNTIF(tbEstoque[Material_ID],tbMateriais[Material_ID])=0)) -> 0 | E22: =IF(D22=0,"PASS","FAIL") -> PASS
A23: Q14 · Nome divergente – Estoque | B23: Material do estoque = catálogo | C23: =IF(D23=0,"Nenhum erro encontrado","Erros encontrados") -> Nenhum erro encontrado | D23: =SUMPRODUCT((COUNTIF(tbMateriais[Material_ID],tbEstoque[Material_ID])>0)*(COUNTIFS(tbMateriais[Material_ID],tbEstoque[Material_ID],tbMateriais[Material],tbEstoque[Material])=0)) -> 0 | E23: =IF(D23=0,"PASS","FAIL") -> PASS
A24: Q15 · Nome divergente – Consumo | B24: Material do consumo = catálogo | C24: =IF(D24=0,"Nenhum erro encontrado","Erros encontrados") -> Nenhum erro encontrado | D24: =SUMPRODUCT((COUNTIF(tbMateriais[Material_ID],tbConsumo[Material_ID])>0)*(COUNTIFS(tbMateriais[Material_ID],tbConsumo[Material_ID],tbMateriais[Material],tbConsumo[Material])=0)) -> 0 | E24: =IF(D24=0,"PASS","FAIL") -> PASS
A25: Q16 · Categoria divergente – Estoque | B25: Categoria do estoque = catálogo | C25: =IF(D25=0,"Nenhum erro encontrado","Erros encontrados") -> Nenhum erro encontrado | D25: =SUMPRODUCT((COUNTIF(tbMateriais[Material_ID],tbEstoque[Material_ID])>0)*(COUNTIFS(tbMateriais[Material_ID],tbEstoque[Material_ID],tbMateriais[Categoria],tbEstoque[Categoria])=0)) -> 0 | E25: =IF(D25=0,"PASS","FAIL") -> PASS
A26: Q17 · Categoria divergente – Consumo | B26: Categoria do consumo = catálogo | C26: =IF(D26=0,"Nenhum erro encontrado","Erros encontrados") -> Nenhum erro encontrado | D26: =SUMPRODUCT((COUNTIF(tbMateriais[Material_ID],tbConsumo[Material_ID])>0)*(COUNTIFS(tbMateriais[Material_ID],tbConsumo[Material_ID],tbMateriais[Categoria],tbConsumo[Categoria])=0)) -> 0 | E26: =IF(D26=0,"PASS","FAIL") -> PASS
A27: Q18 · Unidade divergente – Estoque | B27: Unidade do estoque = catálogo | C27: =IF(D27=0,"Nenhum erro encontrado","Erros encontrados") -> Nenhum erro encontrado | D27: =SUMPRODUCT((COUNTIF(tbMateriais[Material_ID],tbEstoque[Material_ID])>0)*(COUNTIFS(tbMateriais[Material_ID],tbEstoque[Material_ID],tbMateriais[Unidade],tbEstoque[Unidade])=0)) -> 0 | E27: =IF(D27=0,"PASS","FAIL") -> PASS
A28: Q19 · Unidade divergente – Consumo | B28: Unidade do consumo = catálogo | C28: =IF(D28=0,"Nenhum erro encontrado","Erros encontrados") -> Nenhum erro encontrado | D28: =SUMPRODUCT((COUNTIF(tbMateriais[Material_ID],tbConsumo[Material_ID])>0)*(COUNTIFS(tbMateriais[Material_ID],tbConsumo[Material_ID],tbMateriais[Unidade],tbConsumo[Unidade])=0)) -> 0 | E28: =IF(D28=0,"PASS","FAIL") -> PASS
A29: Q20 · Custo divergente – Estoque | B29: Custo_Unitario do estoque = catálogo | C29: =IF(D29=0,"Nenhum erro encontrado","Erros encontrados") -> Nenhum erro encontrado | D29: =SUMPRODUCT((COUNTIF(tbMateriais[Material_ID],tbEstoque[Material_ID])>0)*(COUNTIFS(tbMateriais[Material_ID],tbEstoque[Material_ID],tbMateriais[Custo_Unitario],tbEstoque[Custo_Unitario])=0)) -> 0 | E29: =IF(D29=0,"PASS","FAIL") -> PASS
A30: Q21 · Custo divergente – Consumo | B30: Custo_Unitario do consumo = catálogo | C30: =IF(D30=0,"Nenhum erro encontrado","Erros encontrados") -> Nenhum erro encontrado | D30: =SUMPRODUCT((COUNTIF(tbMateriais[Material_ID],tbConsumo[Material_ID])>0)*(COUNTIFS(tbMateriais[Material_ID],tbConsumo[Material_ID],tbMateriais[Custo_Unitario],tbConsumo[Custo_Unitario])=0)) -> 0 | E30: =IF(D30=0,"PASS","FAIL") -> PASS
A31: Q22 · Criticidade divergente – Estoque | B31: Criticidade do estoque = catálogo | C31: =IF(D31=0,"Nenhum erro encontrado","Erros encontrados") -> Nenhum erro encontrado | D31: =SUMPRODUCT((COUNTIF(tbMateriais[Material_ID],tbEstoque[Material_ID])>0)*(COUNTIFS(tbMateriais[Material_ID],tbEstoque[Material_ID],tbMateriais[Criticidade],tbEstoque[Criticidade])=0)) -> 0 | E31: =IF(D31=0,"PASS","FAIL") -> PASS
A32: Q23 · Fornecedor divergente – Estoque | B32: Fornecedor do estoque = catálogo | C32: =IF(D32=0,"Nenhum erro encontrado","Erros encontrados") -> Nenhum erro encontrado | D32: =SUMPRODUCT((COUNTIF(tbMateriais[Material_ID],tbEstoque[Material_ID])>0)*(COUNTIFS(tbMateriais[Material_ID],tbEstoque[Material_ID],tbMateriais[Fornecedor],tbEstoque[Fornecedor])=0)) -> 0 | E32: =IF(D32=0,"PASS","FAIL") -> PASS
A33: Q24 · Datas inválidas – Consumo | B33: Data válida e dentro do período definido na aba Parametros | C33: =IF(D33=0,"Nenhum erro encontrado","Erros encontrados") -> Nenhum erro encontrado | D33: =SUMPRODUCT(--NOT(ISNUMBER(tbConsumo[Data])))+COUNTIF(tbConsumo[Data],"<"&pInicioPeriodo)+COUNTIF(tbConsumo[Data],">"&pFimPeriodo) -> 0 | E33: =IF(D33=0,"PASS","FAIL") -> PASS
A34: Q25 · Cobertura dos 3 meses – Consumo | B34: Cada mês do período tem >= 1 movimentação (conta meses sem registro) | C34: =IF(D34=0,"Nenhum erro encontrado","Erros encontrados") -> Nenhum erro encontrado | D34: =SUMPRODUCT(--(COUNTIF(tbConsumo[Mes],lstMeses)=0)) -> 0 | E34: =IF(D34=0,"PASS","FAIL") -> PASS
A35: Q26 · Estoque negativo | B35: Estoque_Atual numérico e >= 0 | C35: =IF(D35=0,"Nenhum erro encontrado","Erros encontrados") -> Nenhum erro encontrado | D35: =IF(ROWS(tbEstoque[Estoque_Atual])-COUNT(tbEstoque[Estoque_Atual])>0,ROWS(tbEstoque[Estoque_Atual])-COUNT(tbEstoque[Estoque_Atual]),COUNTIF(tbEstoque[Estoque_Atual],"<0")) -> 0 | E35: =IF(D35=0,"PASS","FAIL") -> PASS
A36: Q27 · Estoque mínimo negativo | B36: Estoque_Minimo numérico e >= 0 | C36: =IF(D36=0,"Nenhum erro encontrado","Erros encontrados") -> Nenhum erro encontrado | D36: =IF(ROWS(tbEstoque[Estoque_Minimo])-COUNT(tbEstoque[Estoque_Minimo])>0,ROWS(tbEstoque[Estoque_Minimo])-COUNT(tbEstoque[Estoque_Minimo]),COUNTIF(tbEstoque[Estoque_Minimo],"<0")) -> 0 | E36: =IF(D36=0,"PASS","FAIL") -> PASS
A37: Q28 · Lead time inválido | B37: Lead_Time_Dias numérico, inteiro e > 0 | C37: =IF(D37=0,"Nenhum erro encontrado","Erros encontrados") -> Nenhum erro encontrado | D37: =IF(ROWS(tbEstoque[Lead_Time_Dias])-COUNT(tbEstoque[Lead_Time_Dias])>0,ROWS(tbEstoque[Lead_Time_Dias])-COUNT(tbEstoque[Lead_Time_Dias]),COUNTIF(tbEstoque[Lead_Time_Dias],"<=0")+SUMPRODUCT(--(tbEstoque[Lead_Time_Dias]<>INT(tbEstoque[Lead_Time_Dias])))) -> 0 | E37: =IF(D37=0,"PASS","FAIL") -> PASS
A38: Q29 · Categoria inválida – Materiais | B38: Categoria pertence à lista permitida | C38: =IF(D38=0,"Nenhum erro encontrado","Erros encontrados") -> Nenhum erro encontrado | D38: =SUMPRODUCT(--(COUNTIF(lstCategorias,tbMateriais[Categoria])=0)) -> 0 | E38: =IF(D38=0,"PASS","FAIL") -> PASS
A39: Q30 · Categoria inválida – Estoque | B39: Categoria pertence à lista permitida | C39: =IF(D39=0,"Nenhum erro encontrado","Erros encontrados") -> Nenhum erro encontrado | D39: =SUMPRODUCT(--(COUNTIF(lstCategorias,tbEstoque[Categoria])=0)) -> 0 | E39: =IF(D39=0,"PASS","FAIL") -> PASS
A40: Q31 · Categoria inválida – Consumo | B40: Categoria pertence à lista permitida | C40: =IF(D40=0,"Nenhum erro encontrado","Erros encontrados") -> Nenhum erro encontrado | D40: =SUMPRODUCT(--(COUNTIF(lstCategorias,tbConsumo[Categoria])=0)) -> 0 | E40: =IF(D40=0,"PASS","FAIL") -> PASS
A41: Q32 · Unidade inválida – Materiais | B41: Unidade em UN, CX, PCT ou PAR | C41: =IF(D41=0,"Nenhum erro encontrado","Erros encontrados") -> Nenhum erro encontrado | D41: =SUMPRODUCT(--(COUNTIF(lstUnidades,tbMateriais[Unidade])=0)) -> 0 | E41: =IF(D41=0,"PASS","FAIL") -> PASS
